Workbook
Name edge_pp: RESULTS!$LV$110
Name ens1NumVoters: RESULTS!$LS$2
Name ens1VoteAgreement: RESULTS!$LV$102
Name FWinThresh: #REF!
Name hWin_Thresh: #REF!
Name HWinThresh: RESULTS!$LV$100
Name kellyFraction: RESULTS!$LV$108
Name MODELPRICE_MAX: RESULTS!$LV$105
Name MODELPRICE_MIN: RESULTS!$LV$104
Name NumGames: RESULTS!$D$3
Name OLE_LINK1: Version_Hist.!#REF!
Name OPL_MAX: RESULTS!$LV$99
Name OPL_MIN: RESULTS!$LV$98
Name OPT_MAX: RESULTS!#REF!
Name OPT_MIN: RESULTS!#REF!
Name stakeMode: RESULTS!$LV$107

Sheet Version_Hist.
A1: Version | B1: Description
A2: V1 | B2: Initial version. Note the 31 trees were trained with "noisy data" due to NAN but predictions unimpacted when evaluated on clean data. Cent_gap bug corrected!
A3: V2 | B3: Probability is now based on ALL models, not just those that agree with majority vote; Flat and Kelly stake mode added; Prices de-vigged; gap in prob not cents
B4: Current invest/return logic is correct but it's welded to a fixed 1-unit-ish stake expressed in cents. The clean way to generalise to Flat and Kelly is to separate the stake from the payout odds. Right now those two are tangled together in your "invest 108 / 102 / 100" cents. Pull them apart into two quantities per game: Stake — how much you risk. This is what the staking mode decides. Payout multiple (b) — how much you win per unit staked if the bet lands. This comes only from the price you're betting, nothing to do with staking mode. Once they're separate, every staking mode is just "compute a stake, multiply through the same payout." You stop having mode-specific invest/return formulas.

Sheet RESULTS
A1: OUTSAMPLE SUMMARY STATS | J1: TEAMS & BOOKIE CLINES | Z1: DATA-BASED HOME PRICES | AD1: OUTCOME | AN1: M1 | AO1: V 119_LineAndStats | AS1: RESULTS DETAIL | AX1: $HF | AZ1: $VD | BB1: $VF | BD1: $HD | BG1: M2 | BH1: V 119_LineAndStats | BL1: RESULTS DETAIL | BQ1: $HF | BS1: $VD | BU1: $VF | BW1: $HD | BZ1: M3 | CA1: V 119_LineAndStats | CE1: RESULTS DETAIL | CJ1: $HF | CL1: $VD | CN1: $VF | CP1: $HD | CS1: M4 | CT1: V 119_LineAndStats | CX1: RESULTS DETAIL | DC1: $HF | DE1: $VD | DG1: $VF | DI1: $HD | DL1: M5 | DM1: V 119_LineAndStats | DQ1: RESULTS DETAIL | DV1: $HF | DX1: $VD | DZ1: $VF | EB1: $HD | EE1: M6 | EF1: V 119_LineAndStats | EJ1: RESULTS DETAIL | EO1: $HF | EQ1: $VD | ES1: $VF | EU1: $HD | EX1: M7 | EY1: V 119_LineAndStats | FC1: RESULTS DETAIL | FH1: $HF | FJ1: $VD | FL1: $VF | FN1: $HD | FQ1: M8 | FR1: V 119_LineAndStats | FV1: RESULTS DETAIL | GA1: $HF | GC1: $VD | GE1: $VF | GG1: $HD | GJ1: M9 | GK1: V 119_LineAndStats | GO1: RESULTS DETAIL | GT1: $HF | GV1: $VD | GX1: $VF | GZ1: $HD | HC1: M10 | HD1: V 119_LineAndStats | HH1: RESULTS DETAIL | HM1: $HF | HO1: $VD | HQ1: $VF | HS1: $HD | HV1: M11 | HW1: V 119_LineAndStats | IA1: RESULTS DETAIL | IF1: $HF | IH1: $VD | IJ1: $VF | IL1: $HD | IO1: M12 | IP1: V 119_LineAndStats | IT1: RESULTS DETAIL | IY1: $HF | JA1: $VD | JC1: $VF | JE1: $HD | JH1: M13 | JI1: V 119_LineAndStats | JM1: RESULTS DETAIL | JR1: $HF | JT1: $VD | JV1: $VF | JX1: $HD | KA1: M14 | KB1: V 119_LineAndStats | KF1: RESULTS DETAIL | KK1: $HF | KM1: $VD | KO1: $VF | KQ1: $HD | KT1: M15 | KU1: V 119_LineAndStats | KY1: RESULTS DETAIL | LD1: $HF | LF1: $VD | LH1: $VF | LJ1: $HD | LO1: ENS#1 | LP1: =AO1 -> V 119_LineAndStats | LS1: #NUM_Voters | LT1: RESULTS DETAIL | LZ1: Avg of Voters Agreeing | MF1: $HF | MH1: $VD | MJ1: $VF | ML1: $HD | MO1: PLAY STAKE/PAYOUT | MS1: PROFIT/LOSS | MX1: Voter H_Win Probabilities
F2: GAME ID | G2: SEASON | H2: MONTHWEEK | I2: DATE | J2: V# | K2: V | L2: V_BML | M2: V_BPL | N2: V_BPL_deVIG | O2: V_BML_deVIG | P2: H# | Q2: H | R2: PARK_IF | S2: H_BML | T2: H_BPL | U2: H_BPL_deVIG | V2: H_BML_deVIG | W2: H_FAVE? | X2: CLT | Y2: CLT_BML | Z2: OFF_MOBSTRGTH20G | AA2: OFF_BOYSPROG | AB2: DEF_SPSOIMPACT | AC2: DEF_BOYSPROG | AD2: V_RUN | AE2: H_RUN | AF2: ABSRUNDIFFCATEG | AG2: H_WIN? | AH2: F_WIN | AI2: WINPOS | AJ2: TOTAL | AK2: IS_OVER_CLT? | AN2: RESULTS SUMMARY | AR2: H Price | AS2: P(H Win) | AT2: Position | AU2: Model_H_Price | AV2: ABS Price | AW2: Win? | AX2: Ret. | AY2: Inv. | AZ2: Ret. | BA2: Inv. | BB2: Ret. | BC2: Inv. | BD2: Ret. | BE2: Inv. | BG2: RESULTS SUMMARY | BK2: H Price | BL2: P(H Win) | BM2: Position | BN2: Model_H_Price | BO2: ABS Price | BP2: Win? | BQ2: Ret. | BR2: Inv. | BS2: Ret. | BT2: Inv. | BU2: Ret. | BV2: Inv. | BW2: Ret. | BX2: Inv. | BZ2: RESULTS SUMMARY | CD2: H Price | CE2: P(H Win) | CF2: Position | CG2: Model_H_Price | CH2: ABS Price | CI2: Win? | CJ2: Ret. | CK2: Inv. | CL2: Ret. | CM2: Inv. | CN2: Ret. | CO2: Inv. | CP2: Ret. | CQ2: Inv. | CS2: RESULTS SUMMARY | CW2: H Price | CX2: P(H Win) | CY2: Position | CZ2: Model_H_Price | DA2: ABS Price | DB2: Win? | DC2: Ret. | DD2: Inv. | DE2: Ret. | DF2: Inv. | DG2: Ret. | DH2: Inv. | DI2: Ret. | DJ2: Inv. | DL2: RESULTS SUMMARY | DP2: H Price | DQ2: P(H Win) | DR2: Position | DS2: Model_H_Price | DT2: ABS Price | DU2: Win? | DV2: Ret. | DW2: Inv. | DX2: Ret. | DY2: Inv. | DZ2: Ret. | EA2: Inv. | EB2: Ret. | EC2: Inv. | EE2: RESULTS SUMMARY | EI2: H Price | EJ2: P(H Win) | EK2: Position | EL2: Model_H_Price | EM2: ABS Price | EN2: Win? | EO2: Ret. | EP2: Inv. | EQ2: Ret. | ER2: Inv. | ES2: Ret. | ET2: Inv. | EU2: Ret. | EV2: Inv. | EX2: RESULTS SUMMARY | FB2: H Price | FC2: P(H Win) | FD2: Position | FE2: Model_H_Price | FF2: ABS Price | FG2: Win? | FH2: Ret. | FI2: Inv. | FJ2: Ret. | FK2: Inv. | FL2: Ret. | FM2: Inv. | FN2: Ret. | FO2: Inv. | FQ2: RESULTS SUMMARY | FU2: H Price | FV2: P(H Win) | FW2: Position | FX2: Model_H_Price | FY2: ABS Price | FZ2: Win? | GA2: Ret. | GB2: Inv. | GC2: Ret. | GD2: Inv. | GE2: Ret. | GF2: Inv. | GG2: Ret. | GH2: Inv. | GJ2: RESULTS SUMMARY | GN2: H Price | GO2: P(H Win) | GP2: Position | GQ2: Model_H_Price | GR2: ABS Price | GS2: Win? | GT2: Ret. | GU2: Inv. | GV2: Ret. | GW2: Inv. | GX2: Ret. | GY2: Inv. | GZ2: Ret. | HA2: Inv. | HC2: RESULTS SUMMARY | HG2: H Price | HH2: P(H Win) | HI2: Position | HJ2: Model_H_Price | HK2: ABS Price | HL2: Win? | HM2: Ret. | HN2: Inv. | HO2: Ret. | HP2: Inv. | HQ2: Ret. | HR2: Inv. | HS2: Ret. | HT2: Inv. | HV2: RESULTS SUMMARY | HZ2: H Price | IA2: P(H Win) | IB2: Position | IC2: Model_H_Price | ID2: ABS Price | IE2: Win? | IF2: Ret. | IG2: Inv. | IH2: Ret. | II2: Inv. | IJ2: Ret. | IK2: Inv. | IL2: Ret. | IM2: Inv. | IO2: RESULTS SUMMARY | IS2: H Price | IT2: P(H Win) | IU2: Position | IV2: Model_H_Price | IW2: ABS Price | IX2: Win? | IY2: Ret. | IZ2: Inv. | JA2: Ret. | JB2: Inv. | JC2: Ret. | JD2: Inv. | JE2: Ret. | JF2: Inv. | JH2: RESULTS SUMMARY | JL2: H Price | JM2: P(H Win) | JN2: Position | JO2: Model_H_Price | JP2: ABS Price | JQ2: Win? | JR2: Ret. | JS2: Inv. | JT2: Ret. | JU2: Inv. | JV2: Ret. | JW2: Inv. | JX2: Ret. | JY2: Inv. | KA2: RESULTS SUMMARY | KE2: H Price | KF2: P(H Win) | KG2: Position | KH2: Model_H_Price | KI2: ABS Price | KJ2: Win? | KK2: Ret. | KL2: Inv. | KM2: Ret. | KN2: Inv. | KO2: Ret. | KP2: Inv. | KQ2: Ret. | KR2: Inv. | KT2: RESULTS SUMMARY | KX2: H Price | KY2: P(H Win) | KZ2: Position | LA2: Model_H_Price | LB2: ABS Price | LC2: Win? | LD2: Ret. | LE2: Inv. | LF2: Ret. | LG2: Inv. | LH2: Ret. | LI2: Inv. | LJ2: Ret. | LK2: Inv. | LN2: =IF(OR(XU3<MODELPRICE_MIN,XU3>MODELPRICE_MAX),"",IF(OR(XV3="VisFave",XV3=""),"",IF(XV3=$AI3,1,-1))) | LO2: RESULTS SUMMARY | LS2: =COUNTA(AN1,BG1,BZ1,CS1,DL1,EE1,EX1,FQ1,GJ1,HC1,HV1,IO1,JH1,KA1,KT1) -> 15 | LT2: Vote_HF | LU2: Vote_VD | LV2: Vote_VF | LW2: Vote_HD | LX2: InitialPOS | LY2: %VotersAgree | LZ2: AvgHProb | MA2: Edge | MB2: AvgHPrice | MC2: FinalPOS | MD2: WinVP&MPGate? | ME2: WinStakeGate? | MF2: Ret. | MG2: Inv. | MH2: Ret. | MI2: Inv. | MJ2: Ret. | MK2: Inv. | ML2: Ret. | MM2: Inv. | MO2: PayoutMulti | MP2: Stake | MS2: Inv | MT2: Ret | MU2: PROFIT | MV2: %ROI | MX2: V1 | MY2: V2 | MZ2: V3 | NA2: V4 | NB2: V5 | NC2: V6 | ND2: V7 | NE2: V8 | NF2: V9 | NG2: V10 | NH2: V11 | NI2: V12 | NJ2: V13 | NK2: V14 | NL2: V15 | NM2: AVG
C3: Num Games | D3: =COUNT(F3:F89) -> 87 | E3: =IF(AND(L3<0,S3<0),1,0) -> 0 | F3: 777623 | G3: =VLOOKUP($F3,Lookup_!$A$2:$AJ$2224,3,FALSE) -> 2025 | H3: =VLOOKUP($F3,Lookup_!$A$2:$AJ$2224,4,FALSE) -> 6.1 | I3: =VLOOKUP($F3,Lookup_!$A$2:$AJ$2224,2,FALSE) -> 45814 | J3: =VLOOKUP($F3,Lookup_!$A$2:$AJ$2224,13,FALSE) -> 1 | K3: =VLOOKUP(J3,Lookup_!$AO$3:$AP$32,2,FALSE) -> ARZ | L3: =VLOOKUP($F3,Lookup_!$A$2:$AJ$2224,14,FALSE) -> -109 | M3: =VLOOKUP($F3,Lookup_!$A$2:$AJ$2224,15,FALSE) -> 0.521531 | N3: =M3/($M3+$T3) -> 0.51178508 | O3: =IF(N3=0.5,100,IF(N3>0.5,N3/(1-N3)*-100, (1-N3)/N3*100)) -> -104.82782 | P3: =VLOOKUP($F3,Lookup_!$A$2:$AJ$2224,7,FALSE) -> 6 | Q3: =VLOOKUP(P3,Lookup_!$AO$3:$AP$32,2,FALSE) -> CIN | R3: =VLOOKUP($F3,Lookup_!$A$2:$AJ$2224,12,FALSE) -> 0.33320854 | S3: =VLOOKUP($F3,Lookup_!$A$2:$AJ$2224,8,FALSE) -> 101 | T3: =VLOOKUP($F3,Lookup_!$A$2:$AJ$2224,9,FALSE) -> 0.497512 | U3: =T3/($M3+$T3) -> 0.48821492 | V3: =IF(U3=0.5,100,IF(U3>0.5,U3/(1-U3)*-100, (1-U3)/U3*100)) -> 104.82782 | W3: =IF(S3<L3,1,-1) -> -1 | X3: =VLOOKUP($F3,Lookup_!$A$2:$AJ$2224,5,FALSE) -> 9.5 | Y3: =VLOOKUP($F3,Lookup_!$A$2:$AJ$2224,6,FALSE) -> 108.5 | Z3: =VLOOKUP($F3,Lookup_!$A$2:$AJ$2224,19,FALSE) -> 102.17965 | AA3: =VLOOKUP($F3,Lookup_!$A$2:$AJ$2224,25,FALSE) -> 124.98706 | AB3: =VLOOKUP($F3,Lookup_!$A$2:$AJ$2224,21,FALSE) -> -100.73618 | AC3: =VLOOKUP($F3,Lookup_!$A$2:$AJ$2224,23,FALSE) -> -105.18755 | AD3: =VLOOKUP($F3,Lookup_!$A$2:$AJ$2224,31,FALSE) -> 3 | AE3: =VLOOKUP($F3,Lookup_!$A$2:$AJ$2224,30,FALSE) -> 4 | AF3: =VLOOKUP($F3,Lookup_!$A$2:$AJ$2224,32,FALSE) -> LTE1 | AG3: =VLOOKUP($F3,Lookup_!$A$2:$AJ$2224,29,FALSE) -> 1 | AH3: =VLOOKUP($F3,Lookup_!$A$2:$AJ$2224,34,FALSE) -> -1 | AI3: =VLOOKUP($F3,Lookup_!$A$2:$AJ$2224,33,FALSE) -> HomDog | AJ3: =VLOOKUP($F3,Lookup_!$A$2:$AJ$2224,35,FALSE) -> 7 | AK3: =VLOOKUP($F3,Lookup_!$A$2:$AJ$2224,36,FALSE) -> -1 | AL3: =ABS(AD3-AE3) -> 1 | AM3: =ABS(AL3) -> 1 | AR3: =$S3 -> 101 | AS3: =IF(OR($S3<OPL_MIN,$S3>OPL_MAX),"",VLOOKUP($F3,CleanseResults!$L$3:$P$1772,5,FALSE)) -> 0.49 | AT3: =IF(AS3="","",IF($W3=1,IF(AS3>=HWinThresh,"HomFave","VisDog"),IF(AS3<HWinThresh,"VisFave","HomDog"))) -> VisFave | AU3: =IF(AT3="","",IF(AS3=0.5,100,IF($W3=1,IF(AS3>0.5,AS3/(1-AS3)*-100, (1-AS3)/AS3*100),IF(AS3>0.5,(1-(1-AS3))/(1-AS3)*100,(1-AS3)/(1-(1-AS3))*-100)))) -> -104.08163 | AV3: =IF(AU3="","",ABS(AU3)) -> 104.08163 | AW3: =IF(AV3="","",IF(AT3=$AI3,1,-1)) -> -1 | AX3: =IF(OR(AW3="",AT3<>"HomFave"),"",IF(AW3=1,100+AY3,0)) | AY3: =IF(OR(AW3="",AT3<>"HomFave"),"",ABS($S3)) | AZ3: =IF(OR(AT3<>"VisDog",AW3=""),"",IF(AW3=1,IF($L3<0,100+BA3,ABS($L3)+BA3),0)) | BA3: =IF(OR(AW3="",AT3<>"VisDog"),"",IF($L3<0,ABS($L3),100)) | BB3: =IF(OR(AW3="",AT3<>"VisFave"),"",IF(AW3=1,100+BC3,0)) -> 0 | BC3: =IF(OR(AW3="",AT3<>"VisFave"),"",ABS($L3)) -> 109 | BD3: =IF(OR(AT3<>"HomDog",AW3=""),"",IF(AW3=1,IF($S3<0,100+BE3,ABS($S3)+BE3),0)) | BE3: =IF(OR(AW3="",AT3<>"HomDog"),"",IF($S3<0,ABS($S3),100)) | BK3: =$S3 -> 101 | BL3: =IF(OR($S3<OPL_MIN,$S3>OPL_MAX),"",VLOOKUP($F3,CleanseResults!$AA$3:$AE$1772,5,FALSE)) -> 0.51 | BM3: =IF(BL3="","",IF($W3=1,IF(BL3>=HWinThresh,"HomFave","VisDog"),IF(BL3<HWinThresh,"VisFave","HomDog"))) -> HomDog | BN3: =IF(BM3="","",IF(BL3=0.5,100,IF($W3=1,IF(BL3>0.5,BL3/(1-BL3)*-100, (1-BL3)/BL3*100),IF(BL3>0.5,(1-(1-BL3))/(1-BL3)*100,(1-BL3)/(1-(1-BL3))*-100)))) -> 104.08163 | BO3: =IF(BN3="","",ABS(BN3)) -> 104.08163 | BP3: =IF(BO3="","",IF(BM3=$AI3,1,-1)) -> 1 | BQ3: =IF(OR(BP3="",BM3<>"HomFave"),"",IF(BP3=1,100+BR3,0)) | BR3: =IF(OR(BP3="",BM3<>"HomFave"),"",ABS($S3)) | BS3: =IF(OR(BM3<>"VisDog",BP3=""),"",IF(BP3=1,IF($L3<0,100+BT3,ABS($L3)+BT3),0)) | BT3: =IF(OR(BP3="",BM3<>"VisDog"),"",IF($L3<0,ABS($L3),100)) | BU3: =IF(OR(BP3="",BM3<>"VisFave"),"",IF(BP3=1,100+BV3,0)) | BV3: =IF(OR(BP3="",BM3<>"VisFave"),"",ABS($L3)) | BW3: =IF(OR(BM3<>"HomDog",BP3=""),"",IF(BP3=1,IF($S3<0,100+BX3,ABS($S3)+BX3),0)) -> 201 | BX3: =IF(OR(BP3="",BM3<>"HomDog"),"",IF($S3<0,ABS($S3),100)) -> 100 | CD3: =$S3 -> 101 | CE3: =IF(OR($S3<OPL_MIN,$S3>OPL_MAX),"",VLOOKUP($F3,CleanseResults!$AP$3:$AT$1772,5,FALSE)) -> 0.4 | CF3: =IF(CE3="","",IF($W3=1,IF(CE3>=HWinThresh,"HomFave","VisDog"),IF(CE3<HWinThresh,"VisFave","HomDog"))) -> VisFave | CG3: =IF(CF3="","",IF(CE3=0.5,100,IF($W3=1,IF(CE3>0.5,CE3/(1-CE3)*-100, (1-CE3)/CE3*100),IF(CE3>0.5,(1-(1-CE3))/(1-CE3)*100,(1-CE3)/(1-(1-CE3))*-100)))) -> -150 | CH3: =IF(CG3="","",ABS(CG3)) -> 150 | CI3: =IF(CH3="","",IF(CF3=$AI3,1,-1)) -> -1 | CJ3: =IF(OR(CI3="",CF3<>"HomFave"),"",IF(CI3=1,100+CK3,0)) | CK3: =IF(OR(CI3="",CF3<>"HomFave"),"",ABS($S3)) | CL3: =IF(OR(CF3<>"VisDog",CI3=""),"",IF(CI3=1,IF($L3<0,100+CM3,ABS($L3)+CM3),0)) | CM3: =IF(OR(CI3="",CF3<>"VisDog"),"",IF($L3<0,ABS($L3),100)) | CN3: =IF(OR(CI3="",CF3<>"VisFave"),"",IF(CI3=1,100+CO3,0)) -> 0 | CO3: =IF(OR(CI3="",CF3<>"VisFave"),"",ABS($L3)) -> 109 | CP3: =IF(OR(CF3<>"HomDog",CI3=""),"",IF(CI3=1,IF($S3<0,100+CQ3,ABS($S3)+CQ3),0)) | CQ3: =IF(OR(CI3="",CF3<>"HomDog"),"",IF($S3<0,ABS($S3),100)) | CW3: =$S3 -> 101 | CX3: =IF(OR($S3<OPL_MIN,$S3>OPL_MAX),"",VLOOKUP($F3,CleanseResults!$BE$3:$BI$1772,5,FALSE)) -> 0.52 | CY3: =IF(CX3="","",IF($W3=1,IF(CX3>=HWinThresh,"HomFave","VisDog"),IF(CX3<HWinThresh,"VisFave","HomDog"))) -> HomDog | CZ3: =IF(CY3="","",IF(CX3=0.5,100,IF($W3=1,IF(CX3>0.5,CX3/(1-CX3)*-100, (1-CX3)/CX3*100),IF(CX3>0.5,(1-(1-CX3))/(1-CX3)*100,(1-CX3)/(1-(1-CX3))*-100)))) -> 108.33333 | DA3: =IF(CZ3="","",ABS(CZ3)) -> 108.33333 | DB3: =IF(DA3="","",IF(CY3=$AI3,1,-1)) -> 1 | DC3: =IF(OR(DB3="",CY3<>"HomFave"),"",IF(DB3=1,100+DD3,0)) | DD3: =IF(OR(DB3="",CY3<>"HomFave"),"",ABS($S3)) | DE3: =IF(OR(CY3<>"VisDog",DB3=""),"",IF(DB3=1,IF($L3<0,100+DF3,ABS($L3)+DF3),0)) | DF3: =IF(OR(DB3="",CY3<>"VisDog"),"",IF($L3<0,ABS($L3),100)) | DG3: =IF(OR(DB3="",CY3<>"VisFave"),"",IF(DB3=1,100+DH3,0)) | DH3: =IF(OR(DB3="",CY3<>"VisFave"),"",ABS($L3)) | DI3: =IF(OR(CY3<>"HomDog",DB3=""),"",IF(DB3=1,IF($S3<0,100+DJ3,ABS($S3)+DJ3),0)) -> 201 | DJ3: =IF(OR(DB3="",CY3<>"HomDog"),"",IF($S3<0,ABS($S3),100)) -> 100 | DP3: =$S3 -> 101 | DQ3: =IF(OR($S3<OPL_MIN,$S3>OPL_MAX),"",VLOOKUP($F3,CleanseResults!$BT$3:$BX$1772,5,FALSE)) -> 0.26 | DR3: =IF(DQ3="","",IF($W3=1,IF(DQ3>=HWinThresh,"HomFave","VisDog"),IF(DQ3<HWinThresh,"VisFave","HomDog"))) -> VisFave | DS3: =IF(DR3="","",IF(DQ3=0.5,100,IF($W3=1,IF(DQ3>0.5,DQ3/(1-DQ3)*-100, (1-DQ3)/DQ3*100),IF(DQ3>0.5,(1-(1-DQ3))/(1-DQ3)*100,(1-DQ3)/(1-(1-DQ3))*-100)))) -> -284.61538 | DT3: =IF(DS3="","",ABS(DS3)) -> 284.61538 | DU3: =IF(DT3="","",IF(DR3=$AI3,1,-1)) -> -1 | DV3: =IF(OR(DU3="",DR3<>"HomFave"),"",IF(DU3=1,100+DW3,0)) | DW3: =IF(OR(DU3="",DR3<>"HomFave"),"",ABS($S3)) | DX3: =IF(OR(DR3<>"VisDog",DU3=""),"",IF(DU3=1,IF($L3<0,100+DY3,ABS($L3)+DY3),0)) | DY3: =IF(OR(DU3="",DR3<>"VisDog"),"",IF($L3<0,ABS($L3),100)) | DZ3: =IF(OR(DU3="",DR3<>"VisFave"),"",IF(DU3=1,100+EA3,0)) -> 0 | EA3: =IF(OR(DU3="",DR3<>"VisFave"),"",ABS($L3)) -> 109 | EB3: =IF(OR(DR3<>"HomDog",DU3=""),"",IF(DU3=1,IF($S3<0,100+EC3,ABS($S3)+EC3),0)) | EC3: =IF(OR(DU3="",DR3<>"HomDog"),"",IF($S3<0,ABS($S3),100)) | EI3: =$S3 -> 101 | EJ3: =IF(OR($S3<OPL_MIN,$S3>OPL_MAX),"",VLOOKUP($F3,CleanseResults!$CI$3:$CM$1772,5,FALSE)) -> 0.41 | EK3: =IF(EJ3="","",IF($W3=1,IF(EJ3>=HWinThresh,"HomFave","VisDog"),IF(EJ3<HWinThresh,"VisFave","HomDog"))) -> VisFave | EL3: =IF(EK3="","",IF(EJ3=0.5,100,IF($W3=1,IF(EJ3>0.5,EJ3/(1-EJ3)*-100, (1-EJ3)/EJ3*100),IF(EJ3>0.5,(1-(1-EJ3))/(1-EJ3)*100,(1-EJ3)/(1-(1-EJ3))*-100)))) -> -143.90244 | EM3: =IF(EL3="","",ABS(EL3)) -> 143.90244 | EN3: =IF(EM3="","",IF(EK3=$AI3,1,-1)) -> -1 | EO3: =IF(OR(EN3="",EK3<>"HomFave"),"",IF(EN3=1,100+EP3,0)) | EP3: =IF(OR(EN3="",EK3<>"HomFave"),"",ABS($S3)) | EQ3: =IF(OR(EK3<>"VisDog",EN3=""),"",IF(EN3=1,IF($L3<0,100+ER3,ABS($L3)+ER3),0)) | ER3: =IF(OR(EN3="",EK3<>"VisDog"),"",IF($L3<0,ABS($L3),100)) | ES3: =IF(OR(EN3="",EK3<>"VisFave"),"",IF(EN3=1,100+ET3,0)) -> 0 | ET3: =IF(OR(EN3="",EK3<>"VisFave"),"",ABS($L3)) -> 109 | EU3: =IF(OR(EK3<>"HomDog",EN3=""),"",IF(EN3=1,IF($S3<0,100+EV3,ABS($S3)+EV3),0)) | EV3: =IF(OR(EN3="",EK3<>"HomDog"),"",IF($S3<0,ABS($S3),100)) | FB3: =$S3 -> 101 | FC3: =IF(OR($S3<OPL_MIN,$S3>OPL_MAX),"",VLOOKUP($F3,CleanseResults!$CX$3:$DB$1772,5,FALSE)) -> 0.46 | FD3: =IF(FC3="","",IF($W3=1,IF(FC3>=HWinThresh,"HomFave","VisDog"),IF(FC3<HWinThresh,"VisFave","HomDog"))) -> VisFave | FE3: =IF(FD3="","",IF(FC3=0.5,100,IF($W3=1,IF(FC3>0.5,FC3/(1-FC3)*-100, (1-FC3)/FC3*100),IF(FC3>0.5,(1-(1-FC3))/(1-FC3)*100,(1-FC3)/(1-(1-FC3))*-100)))) -> -117.3913 | FF3: =IF(FE3="","",ABS(FE3)) -> 117.3913 | FG3: =IF(FF3="","",IF(FD3=$AI3,1,-1)) -> -1 | FH3: =IF(OR(FG3="",FD3<>"HomFave"),"",IF(FG3=1,100+FI3,0)) | FI3: =IF(OR(FG3="",FD3<>"HomFave"),"",ABS($S3)) | FJ3: =IF(OR(FD3<>"VisDog",FG3=""),"",IF(FG3=1,IF($L3<0,100+FK3,ABS($L3)+FK3),0)) | FK3: =IF(OR(FG3="",FD3<>"VisDog"),"",IF($L3<0,ABS($L3),100)) | FL3: =IF(OR(FG3="",FD3<>"VisFave"),"",IF(FG3=1,100+FM3,0)) -> 0 | FM3: =IF(OR(FG3="",FD3<>"VisFave"),"",ABS($L3)) -> 109 | FN3: =IF(OR(FD3<>"HomDog",FG3=""),"",IF(FG3=1,IF($S3<0,100+FO3,ABS($S3)+FO3),0)) | FO3: =IF(OR(FG3="",FD3<>"HomDog"),"",IF($S3<0,ABS($S3),100)) | FU3: =$S3 -> 101 | FV3: =IF(OR($S3<OPL_MIN,$S3>OPL_MAX),"",VLOOKUP($F3,CleanseResults!$DM$3:$DQ$1772,5,FALSE)) -> 0.42 | FW3: =IF(FV3="","",IF($W3=1,IF(FV3>=HWinThresh,"HomFave","VisDog"),IF(FV3<HWinThresh,"VisFave","HomDog"))) -> VisFave | FX3: =IF(FW3="","",IF(FV3=0.5,100,IF($W3=1,IF(FV3>0.5,FV3/(1-FV3)*-100, (1-FV3)/FV3*100),IF(FV3>0.5,(1-(1-FV3))/(1-FV3)*100,(1-FV3)/(1-(1-FV3))*-100)))) -> -138.09524 | FY3: =IF(FX3="","",ABS(FX3)) -> 138.09524 | FZ3: =IF(FY3="","",IF(FW3=$AI3,1,-1)) -> -1 | GA3: =IF(OR(FZ3="",FW3<>"HomFave"),"",IF(FZ3=1,100+GB3,0)) | GB3: =IF(OR(FZ3="",FW3<>"HomFave"),"",ABS($S3)) | GC3: =IF(OR(FW3<>"VisDog",FZ3=""),"",IF(FZ3=1,IF($L3<0,100+GD3,ABS($L3)+GD3),0)) | GD3: =IF(OR(FZ3="",FW3<>"VisDog"),"",IF($L3<0,ABS($L3),100)) | GE3: =IF(OR(FZ3="",FW3<>"VisFave"),"",IF(FZ3=1,100+GF3,0)) -> 0 | GF3: =IF(OR(FZ3="",FW3<>"VisFave"),"",ABS($L3)) -> 109 | GG3: =IF(OR(FW3<>"HomDog",FZ3=""),"",IF(FZ3=1,IF($S3<0,100+GH3,ABS($S3)+GH3),0)) | GH3: =IF(OR(FZ3="",FW3<>"HomDog"),"",IF($S3<0,ABS($S3),100)) | GN3: =$S3 -> 101 | GO3: =IF(OR($S3<OPL_MIN,$S3>OPL_MAX),"",VLOOKUP($F3,CleanseResults!$EB$3:$EF$1772,5,FALSE)) -> 0.46 | GP3: =IF(GO3="","",IF($W3=1,IF(GO3>=HWinThresh,"HomFave","VisDog"),IF(GO3<HWinThresh,"VisFave","HomDog"))) -> VisFave | GQ3: =IF(GP3="","",IF(GO3=0.5,100,IF($W3=1,IF(GO3>0.5,GO3/(1-GO3)*-100, (1-GO3)/GO3*100),IF(GO3>0.5,(1-(1-GO3))/(1-GO3)*100,(1-GO3)/(1-(1-GO3))*-100)))) -> -117.3913 | GR3: =IF(GQ3="","",ABS(GQ3)) -> 117.3913 | GS3: =IF(GR3="","",IF(GP3=$AI3,1,-1)) -> -1 | GT3: =IF(OR(GS3="",GP3<>"HomFave"),"",IF(GS3=1,100+GU3,0)) | GU3: =IF(OR(GS3="",GP3<>"HomFave"),"",ABS($S3)) | GV3: =IF(OR(GP3<>"VisDog",GS3=""),"",IF(GS3=1,IF($L3<0,100+GW3,ABS($L3)+GW3),0)) | GW3: =IF(OR(GS3="",GP3<>"VisDog"),"",IF($L3<0,ABS($L3),100)) | GX3: =IF(OR(GS3="",GP3<>"VisFave"),"",IF(GS3=1,100+GY3,0)) -> 0 | GY3: =IF(OR(GS3="",GP3<>"VisFave"),"",ABS($L3)) -> 109 | GZ3: =IF(OR(GP3<>"HomDog",GS3=""),"",IF(GS3=1,IF($S3<0,100+HA3,ABS($S3)+HA3),0)) | HA3: =IF(OR(GS3="",GP3<>"HomDog"),"",IF($S3<0,ABS($S3),100)) | HG3: =$S3 -> 101 | HH3: =IF(OR($S3<OPL_MIN,$S3>OPL_MAX),"",VLOOKUP($F3,CleanseResults!$EQ$3:$EU$1772,5,FALSE)) -> 0.46 | HI3: =IF(HH3="","",IF($W3=1,IF(HH3>=HWinThresh,"HomFave","VisDog"),IF(HH3<HWinThresh,"VisFave","HomDog"))) -> VisFave | HJ3: =IF(HI3="","",IF(HH3=0.5,100,IF($W3=1,IF(HH3>0.5,HH3/(1-HH3)*-100, (1-HH3)/HH3*100),IF(HH3>0.5,(1-(1-HH3))/(1-HH3)*100,(1-HH3)/(1-(1-HH3))*-100)))) -> -117.3913 | HK3: =IF(HJ3="","",ABS(HJ3)) -> 117.3913 | HL3: =IF(HK3="","",IF(HI3=$AI3,1,-1)) -> -1 | HM3: =IF(OR(HL3="",HI3<>"HomFave"),"",IF(HL3=1,100+HN3,0)) | HN3: =IF(OR(HL3="",HI3<>"HomFave"),"",ABS($S3)) | HO3: =IF(OR(HI3<>"VisDog",HL3=""),"",IF(HL3=1,IF($L3<0,100+HP3,ABS($L3)+HP3),0)) | HP3: =IF(OR(HL3="",HI3<>"VisDog"),"",IF($L3<0,ABS($L3),100)) | HQ3: =IF(OR(HL3="",HI3<>"VisFave"),"",IF(HL3=1,100+HR3,0)) -> 0 | HR3: =IF(OR(HL3="",HI3<>"VisFave"),"",ABS($L3)) -> 109 | HS3: =IF(OR(HI3<>"HomDog",HL3=""),"",IF(HL3=1,IF($S3<0,100+HT3,ABS($S3)+HT3),0)) | HT3: =IF(OR(HL3="",HI3<>"HomDog"),"",IF($S3<0,ABS($S3),100)) | HZ3: =$S3 -> 101 | IA3: =IF(OR($S3<OPL_MIN,$S3>OPL_MAX),"",VLOOKUP($F3,CleanseResults!$FF$3:$FJ$1772,5,FALSE)) -> 0.49 | IB3: =IF(IA3="","",IF($W3=1,IF(IA3>=HWinThresh,"HomFave","VisDog"),IF(IA3<HWinThresh,"VisFave","HomDog"))) -> VisFave | IC3: =IF(IB3="","",IF(IA3=0.5,100,IF($W3=1,IF(IA3>0.5,IA3/(1-IA3)*-100, (1-IA3)/IA3*100),IF(IA3>0.5,(1-(1-IA3))/(1-IA3)*100,(1-IA3)/(1-(1-IA3))*-100)))) -> -104.08163 | ID3: =IF(IC3="","",ABS(IC3)) -> 104.08163 | IE3: =IF(ID3="","",IF(IB3=$AI3,1,-1)) -> -1 | IF3: =IF(OR(IE3="",IB3<>"HomFave"),"",IF(IE3=1,100+IG3,0)) | IG3: =IF(OR(IE3="",IB3<>"HomFave"),"",ABS($S3)) | IH3: =IF(OR(IB3<>"VisDog",IE3=""),"",IF(IE3=1,IF($L3<0,100+II3,ABS($L3)+II3),0)) | II3: =IF(OR(IE3="",IB3<>"VisDog"),"",IF($L3<0,ABS($L3),100)) | IJ3: =IF(OR(IE3="",IB3<>"VisFave"),"",IF(IE3=1,100+IK3,0)) -> 0 | IK3: =IF(OR(IE3="",IB3<>"VisFave"),"",ABS($L3)) -> 109 | IL3: =IF(OR(IB3<>"HomDog",IE3=""),"",IF(IE3=1,IF($S3<0,100+IM3,ABS($S3)+IM3),0)) | IM3: =IF(OR(IE3="",IB3<>"HomDog"),"",IF($S3<0,ABS($S3),100)) | IS3: =$S3 -> 101 | IT3: =IF(OR($S3<OPL_MIN,$S3>OPL_MAX),"",VLOOKUP($F3,CleanseResults!$FU$3:$FY$1772,5,FALSE)) -> 0.47 | IU3: =IF(IT3="","",IF($W3=1,IF(IT3>=HWinThresh,"HomFave","VisDog"),IF(IT3<HWinThresh,"VisFave","HomDog"))) -> VisFave | IV3: =IF(IU3="","",IF(IT3=0.5,100,IF($W3=1,IF(IT3>0.5,IT3/(1-IT3)*-100, (1-IT3)/IT3*100),IF(IT3>0.5,(1-(1-IT3))/(1-IT3)*100,(1-IT3)/(1-(1-IT3))*-100)))) -> -112.76596 | IW3: =IF(IV3="","",ABS(IV3)) -> 112.76596 | IX3: =IF(IW3="","",IF(IU3=$AI3,1,-1)) -> -1 | IY3: =IF(OR(IX3="",IU3<>"HomFave"),"",IF(IX3=1,100+IZ3,0)) | IZ3: =IF(OR(IX3="",IU3<>"HomFave"),"",ABS($S3)) | JA3: =IF(OR(IU3<>"VisDog",IX3=""),"",IF(IX3=1,IF($L3<0,100+JB3,ABS($L3)+JB3),0)) | JB3: =IF(OR(IX3="",IU3<>"VisDog"),"",IF($L3<0,ABS($L3),100)) | JC3: =IF(OR(IX3="",IU3<>"VisFave"),"",IF(IX3=1,100+JD3,0)) -> 0 | JD3: =IF(OR(IX3="",IU3<>"VisFave"),"",ABS($L3)) -> 109 | JE3: =IF(OR(IU3<>"HomDog",IX3=""),"",IF(IX3=1,IF($S3<0,100+JF3,ABS($S3)+JF3),0)) | JF3: =IF(OR(IX3="",IU3<>"HomDog"),"",IF($S3<0,ABS($S3),100)) | JL3: =$S3 -> 101 | JM3: =IF(OR($S3<OPL_MIN,$S3>OPL_MAX),"",VLOOKUP($F3,CleanseResults!$GJ$3:$GN$1772,5,FALSE)) -> 0.44 | JN3: =IF(JM3="","",IF($W3=1,IF(JM3>=HWinThresh,"HomFave","VisDog"),IF(JM3<HWinThresh,"VisFave","HomDog"))) -> VisFave | JO3: =IF(JN3="","",IF(JM3=0.5,100,IF($W3=1,IF(JM3>0.5,JM3/(1-JM3)*-100, (1-JM3)/JM3*100),IF(JM3>0.5,(1-(1-JM3))/(1-JM3)*100,(1-JM3)/(1-(1-JM3))*-100)))) -> -127.27273 | JP3: =IF(JO3="","",ABS(JO3)) -> 127.27273 | JQ3: =IF(JP3="","",IF(JN3=$AI3,1,-1)) -> -1 | JR3: =IF(OR(JQ3="",JN3<>"HomFave"),"",IF(JQ3=1,100+JS3,0)) | JS3: =IF(OR(JQ3="",JN3<>"HomFave"),"",ABS($S3)) | JT3: =IF(OR(JN3<>"VisDog",JQ3=""),"",IF(JQ3=1,IF($L3<0,100+JU3,ABS($L3)+JU3),0)) | JU3: =IF(OR(JQ3="",JN3<>"VisDog"),"",IF($L3<0,ABS($L3),100)) | JV3: =IF(OR(JQ3="",JN3<>"VisFave"),"",IF(JQ3=1,100+JW3,0)) -> 0 | JW3: =IF(OR(JQ3="",JN3<>"VisFave"),"",ABS($L3)) -> 109 | JX3: =IF(OR(JN3<>"HomDog",JQ3=""),"",IF(JQ3=1,IF($S3<0,100+JY3,ABS($S3)+JY3),0)) | JY3: =IF(OR(JQ3="",JN3<>"HomDog"),"",IF($S3<0,ABS($S3),100)) | KE3: =$S3 -> 101 | KF3: =IF(OR($S3<OPL_MIN,$S3>OPL_MAX),"",VLOOKUP($F3,CleanseResults!$GY$3:$HC$1772,5,FALSE)) -> 0.43 | KG3: =IF(KF3="","",IF($W3=1,IF(KF3>=HWinThresh,"HomFave","VisDog"),IF(KF3<HWinThresh,"VisFave","HomDog"))) -> VisFave | KH3: =IF(KG3="","",IF(KF3=0.5,100,IF($W3=1,IF(KF3>0.5,KF3/(1-KF3)*-100, (1-KF3)/KF3*100),IF(KF3>0.5,(1-(1-KF3))/(1-KF3)*100,(1-KF3)/(1-(1-KF3))*-100)))) -> -132.55814 | KI3: =IF(KH3="","",ABS(KH3)) -> 132.55814 | KJ3: =IF(KI3="","",IF(KG3=$AI3,1,-1)) -> -1 | KK3: =IF(OR(KJ3="",KG3<>"HomFave"),"",IF(KJ3=1,100+KL3,0)) | KL3: =IF(OR(KJ3="",KG3<>"HomFave"),"",ABS($S3)) | KM3: =IF(OR(KG3<>"VisDog",KJ3=""),"",IF(KJ3=1,IF($L3<0,100+KN3,ABS($L3)+KN3),0)) | KN3: =IF(OR(KJ3="",KG3<>"VisDog"),"",IF($L3<0,ABS($L3),100)) | KO3: =IF(OR(KJ3="",KG3<>"VisFave"),"",IF(KJ3=1,100+KP3,0)) -> 0 | KP3: =IF(OR(KJ3="",KG3<>"VisFave"),"",ABS($L3)) -> 109 | KQ3: =IF(OR(KG3<>"HomDog",KJ3=""),"",IF(KJ3=1,IF($S3<0,100+KR3,ABS($S3)+KR3),0)) | KR3: =IF(OR(KJ3="",KG3<>"HomDog"),"",IF($S3<0,ABS($S3),100)) | KX3: =$S3 -> 101 | KY3: =IF(OR($S3<OPL_MIN,$S3>OPL_MAX),"",VLOOKUP($F3,CleanseResults!$HN$3:$HR$1772,5,FALSE)) -> 0.46 | KZ3: =IF(KY3="","",IF($W3=1,IF(KY3>=HWinThresh,"HomFave","VisDog"),IF(KY3<HWinThresh,"VisFave","HomDog"))) -> VisFave | LA3: =IF(KZ3="","",IF(KY3=0.5,100,IF($W3=1,IF(KY3>0.5,KY3/(1-KY3)*-100, (1-KY3)/KY3*100),IF(KY3>0.5,(1-(1-KY3))/(1-KY3)*100,(1-KY3)/(1-(1-KY3))*-100)))) -> -117.3913 | LB3: =IF(LA3="","",ABS(LA3)) -> 117.3913 | LC3: =IF(LB3="","",IF(KZ3=$AI3,1,-1)) -> -1 | LD3: =IF(OR(LC3="",KZ3<>"HomFave"),"",IF(LC3=1,100+LE3,0)) | LE3: =IF(OR(LC3="",KZ3<>"HomFave"),"",ABS($S3)) | LF3: =IF(OR(KZ3<>"VisDog",LC3=""),"",IF(LC3=1,IF($L3<0,100+LG3,ABS($L3)+LG3),0)) | LG3: =IF(OR(LC3="",KZ3<>"VisDog"),"",IF($L3<0,ABS($L3),100)) | LH3: =IF(OR(LC3="",KZ3<>"VisFave"),"",IF(LC3=1,100+LI3,0)) -> 0 | LI3: =IF(OR(LC3="",KZ3<>"VisFave"),"",ABS($L3)) -> 109 | LJ3: =IF(OR(KZ3<>"HomDog",LC3=""),"",IF(LC3=1,IF($S3<0,100+LK3,ABS($S3)+LK3),0)) | LK3: =IF(OR(LC3="",KZ3<>"HomDog"),"",IF($S3<0,ABS($S3),100)) | LS3: =IF(LX3="","",U3) -> 0.48821492 | LT3: =COUNTIFS($AT3,"=HomFave",$AW3,"=1")+COUNTIFS($AT3,"=HomFave",$AW3,"=-1")+COUNTIFS($BM3,"=HomFave",$BP3,"=1")+COUNTIFS($BM3,"=HomFave",$BP3,"=-1")+COUNTIFS($CF3,"=HomFave",$CI3,"=1")+COUNTIFS($CF3,"=HomFave",$CI3,"=-1")+COUNTIFS($CY3,"=HomFave",$DB3,"=1")+COUNTIFS($CY3,"=HomFave",$DB3,"=-1")+COUNTIFS($DR3,"=HomFave",$DU3,"=1")+COUNTIFS($DR3,"=HomFave",$DU3,"=-1")+COUNTIFS($EK3,"=HomFave",$EN3,"=1")+COUNTIFS($EK3,"=HomFave",$EN3,"=-1")+COUNTIFS($FD3,"=HomFave",$FG3,"=1")+COUNTIFS($FD3,"=HomFave",$FG3,"=-1")+COUNTIFS($FW3,"=HomFave",$FZ3,"=1")+COUNTIFS($FW3,"=HomFave",$FZ3,"=-1")+COUNTIFS($GP3,"=HomFave",$GS3,"=1")+COUNTIFS($GP3,"=HomFave",$GS3,"=-1") +COUNTIFS($HI3,"=HomFave",$HL3,"=1")+COUNTIFS($HI3,"=HomFave",$HL3,"=-1")+COUNTIFS($IB3,"=HomFave",$IE3,"=1")+COUNTIFS($IB3,"=HomFave",$IE3,"=-1")+COUNTIFS($IU3,"=HomFave",$IX3,"=1")+COUNTIFS($IU3,"=HomFave",$IX3,"=-1")+COUNTIFS($JN3,"=HomFave",$JQ3,"=1")+COUNTIFS($JN3,"=HomFave",$JQ3,"=-1")+COUNTIFS($KG3,"=HomFave",$KJ3,"=1")+COUNTIFS($KG3,"=HomFave",$KJ3,"=-1")+COUNTIFS($KZ3,"=HomFave",$LC3,"=1")+COUNTIFS($KZ3,"=HomFave",$LC3,"=-1") -> 0 | LU3: =COUNTIFS($AT3,"=VisDog",$AW3,"=1")+COUNTIFS($AT3,"=VisDog",$AW3,"=-1")+COUNTIFS($BM3,"=VisDog",$BP3,"=1")+COUNTIFS($BM3,"=VisDog",$BP3,"=-1")+COUNTIFS($CF3,"=VisDog",$CI3,"=1")+COUNTIFS($CF3,"=VisDog",$CI3,"=-1")+COUNTIFS($CY3,"=VisDog",$DB3,"=1")+COUNTIFS($CY3,"=VisDog",$DB3,"=-1")+COUNTIFS($DR3,"=VisDog",$DU3,"=1")+COUNTIFS($DR3,"=VisDog",$DU3,"=-1")+COUNTIFS($EK3,"=VisDog",$EN3,"=1")+COUNTIFS($EK3,"=VisDog",$EN3,"=-1")+COUNTIFS($FD3,"=VisDog",$FG3,"=1")+COUNTIFS($FD3,"=VisDog",$FG3,"=-1")+COUNTIFS($FW3,"=VisDog",$FZ3,"=1")+COUNTIFS($FW3,"=VisDog",$FZ3,"=-1")+COUNTIFS($GP3,"=VisDog",$GS3,"=1")+COUNTIFS($GP3,"=VisDog",$GS3,"=-1") +COUNTIFS($HI3,"=VisDog",$HL3,"=1")+COUNTIFS($HI3,"=VisDog",$HL3,"=-1")+COUNTIFS($IB3,"=VisDog",$IE3,"=1")+COUNTIFS($IB3,"=VisDog",$IE3,"=-1")+COUNTIFS($IU3,"=VisDog",$IX3,"=1")+COUNTIFS($IU3,"=VisDog",$IX3,"=-1")+COUNTIFS($JN3,"=VisDog",$JQ3,"=1")+COUNTIFS($JN3,"=VisDog",$JQ3,"=-1")+COUNTIFS($KG3,"=VisDog",$KJ3,"=1")+COUNTIFS($KG3,"=VisDog",$KJ3,"=-1")+COUNTIFS($KZ3,"=VisDog",$LC3,"=1")+COUNTIFS($KZ3,"=VisDog",$LC3,"=-1") -> 0 | LV3: =COUNTIFS($AT3,"=VisFave",$AW3,"=1")+COUNTIFS($AT3,"=VisFave",$AW3,"=-1")+COUNTIFS($BM3,"=VisFave",$BP3,"=1")+COUNTIFS($BM3,"=VisFave",$BP3,"=-1")+COUNTIFS($CF3,"=VisFave",$CI3,"=1")+COUNTIFS($CF3,"=VisFave",$CI3,"=-1")+COUNTIFS($CY3,"=VisFave",$DB3,"=1")+COUNTIFS($CY3,"=VisFave",$DB3,"=-1")+COUNTIFS($DR3,"=VisFave",$DU3,"=1")+COUNTIFS($DR3,"=VisFave",$DU3,"=-1")+COUNTIFS($EK3,"=VisFave",$EN3,"=1")+COUNTIFS($EK3,"=VisFave",$EN3,"=-1")+COUNTIFS($FD3,"=VisFave",$FG3,"=1")+COUNTIFS($FD3,"=VisFave",$FG3,"=-1")+COUNTIFS($FW3,"=VisFave",$FZ3,"=1")+COUNTIFS($FW3,"=VisFave",$FZ3,"=-1")+COUNTIFS($GP3,"=VisFave",$GS3,"=1")+COUNTIFS($GP3,"=VisFave",$GS3,"=-1") +COUNTIFS($HI3,"=VisFave",$HL3,"=1")+COUNTIFS($HI3,"=VisFave",$HL3,"=-1")+COUNTIFS($IB3,"=VisFave",$IE3,"=1")+COUNTIFS($IB3,"=VisFave",$IE3,"=-1")+COUNTIFS($IU3,"=VisFave",$IX3,"=1")+COUNTIFS($IU3,"=VisFave",$IX3,"=-1")+COUNTIFS($JN3,"=VisFave",$JQ3,"=1")+COUNTIFS($JN3,"=VisFave",$JQ3,"=-1")+COUNTIFS($KG3,"=VisFave",$KJ3,"=1")+COUNTIFS($KG3,"=VisFave",$KJ3,"=-1")+COUNTIFS($KZ3,"=VisFave",$LC3,"=1")+COUNTIFS($KZ3,"=VisFave",$LC3,"=-1") -> 13 | LW3: =COUNTIFS($AT3,"=HomDog",$AW3,"=1")+COUNTIFS($AT3,"=HomDog",$AW3,"=-1")+COUNTIFS($BM3,"=HomDog",$BP3,"=1")+COUNTIFS($BM3,"=HomDog",$BP3,"=-1")+COUNTIFS($CF3,"=HomDog",$CI3,"=1")+COUNTIFS($CF3,"=HomDog",$CI3,"=-1")+COUNTIFS($CY3,"=HomDog",$DB3,"=1")+COUNTIFS($CY3,"=HomDog",$DB3,"=-1")+COUNTIFS($DR3,"=HomDog",$DU3,"=1")+COUNTIFS($DR3,"=HomDog",$DU3,"=-1")+COUNTIFS($EK3,"=HomDog",$EN3,"=1")+COUNTIFS($EK3,"=HomDog",$EN3,"=-1")+COUNTIFS($FD3,"=HomDog",$FG3,"=1")+COUNTIFS($FD3,"=HomDog",$FG3,"=-1")+COUNTIFS($FW3,"=HomDog",$FZ3,"=1")+COUNTIFS($FW3,"=HomDog",$FZ3,"=-1")+COUNTIFS($GP3,"=HomDog",$GS3,"=1")+COUNTIFS($GP3,"=HomDog",$GS3,"=-1") +COUNTIFS($HI3,"=HomDog",$HL3,"=1")+COUNTIFS($HI3,"=HomDog",$HL3,"=-1")+COUNTIFS($IB3,"=HomDog",$IE3,"=1")+COUNTIFS($IB3,"=HomDog",$IE3,"=-1")+COUNTIFS($IU3,"=HomDog",$IX3,"=1")+COUNTIFS($IU3,"=HomDog",$IX3,"=-1")+COUNTIFS($JN3,"=HomDog",$JQ3,"=1")+COUNTIFS($JN3,"=HomDog",$JQ3,"=-1")+COUNTIFS($KG3,"=HomDog",$KJ3,"=1")+COUNTIFS($KG3,"=HomDog",$KJ3,"=-1")+COUNTIFS($KZ3,"=HomDog",$LC3,"=1")+COUNTIFS($KZ3,"=HomDog",$LC3,"=-1") -> 2 | LX3: =IF($S3<$L3,IF(LT3>LU3,IF((ens1NumVoters-SUM(LT3,LU3))>LT3,"",IF((LT3/(LT3+LU3))>=ens1VoteAgreement,"HomFave","")),IF((ens1NumVoters-SUM(LT3,LU3))>LU3,"",IF((LU3/(LT3+LU3))>=ens1VoteAgreement,"VisDog",""))),IF(LV3>LW3,IF((ens1NumVoters-SUM(LV3,LW3))>LV3,"",IF((LV3/(LV3+LW3))>=ens1VoteAgreement,"VisFave","")),IF((ens1NumVoters-SUM(LV3,LW3))>LW3,"",IF((LW3/(LV3+LW3))>=ens1VoteAgreement,"HomDog","")))) -> VisFave | LY3: =IF(MC3="","",IF(LX3="HomFave",(LT3/$LS$2)*100,IF(LX3="VisDog",(LU3/$LS$2)*100,IF(LX3="VisFave",(LV3/$LS$2)*100,(LW3/$LS$2)*100)))) -> 86.666667 | LZ3: =IF(LX3="","",NM3) -> 0.46 | MA3: =IF(LX3="","",LZ3-$U3) -> -0.028214923 | MB3: =IF(LZ3="","",IF(LZ3=0.5,100,IF($W3=1,IF(LZ3>0.5,LZ3/(1-LZ3)*-100,(1-LZ3)/LZ3*100), IF(LZ3<0.5,(1-LZ3)/LZ3*100,LZ3/(1-LZ3)*-100)))) -> 117.3913 | MC3: =IF(LX3="","", IF(edge_pp=0, LX3, IF(OR(LX3="HomFave",LX3="HomDog"), IF(MA3 >= edge_pp, LX3, ""), IF(MA3 <= -edge_pp, LX3, "")))) -> VisFave | MD3: =IF(OR(MB3<MODELPRICE_MIN,MB3>MODELPRICE_MAX),"",IF(OR(MC3="VisFave",MC3=""),"",IF(MC3=$AI3,1,-1))) | ME3: =IF(OR(MP3="",MP3=0),"",IF(MC3=$AI3,1,-1)) | MF3: =IF(OR(ME3="",MC3<>"HomFave"),"",IF(ME3=1,MP3*(1+MO3),0)) | MG3: =IF(OR(ME3="",MC3<>"HomFave"),"",MP3) | MH3: =IF(OR(MC3<>"VisDog",ME3=""),"",IF(ME3=1,MP3*(1+MO3),0)) | MI3: =IF(OR(ME3="",MC3<>"VisDog"),"",MP3) | MJ3: =IF(OR(ME3="",MC3<>"VisFave"),"",IF(ME3=1,MP3*(1+MO3),0)) | MK3: =IF(OR(ME3="",MC3<>"VisFave"),"",MP3) | ML3: =IF(OR(MC3<>"HomDog",ME3=""),"",IF(ME3=1,MP3*(1+MO3),0)) | MM3: =IF(OR(ME3="",MC3<>"HomDog"),"",MP3) | MO3: =IF($MD3="","",IF(OR($MC3="HomFave",$MC3="HomDog"),IF($S3<0,100/ABS($S3),$S3/100),IF($L3<0,100/ABS($L3),$L3/100))) | MP3: =IF($MD3="","", IF(stakeMode=1, 1, IF(OR($MC3="HomFave",$MC3="HomDog"), kellyFraction*MAX(0, $LZ3 - (1-$LZ3)/$MO3), kellyFraction*MAX(0, (1-$LZ3) - $LZ3/$MO3)))) | MS3: =IF($ME3="","",MP3) | MT3: =IF($ME3="","",IF(ME3=1,MP3*(1+MO3),0)) | MU3: =IF($ME3="","",IF(ME3=1,MP3*MO3,-1*MP3)) | MV3: =IF($ME3="","",IF(MS3=0,0,MU3/MS3)) | MX3: =IF($LX3="","",AS3) -> 0.49 | MY3: =IF($LX3="","",BL3) -> 0.51 | MZ3: =IF($LX3="","",CE3) -> 0.4 | NA3: =IF($LX3="","",CX3) -> 0.52 | NB3: =IF($LX3="","",DQ3) -> 0.26 | NC3: =IF($LX3="","",EJ3) -> 0.41 | ND3: =IF($LX3="","",FC3) -> 0.46 | NE3: =IF($LX3="","",FV3) -> 0.42 | NF3: =IF($LX3="","",GO3) -> 0.46 | NG3: =IF($LX3="","",HH3) -> 0.46 | NH3: =IF($LX3="","",IA3) -> 0.49 | NI3: =IF($LX3="","",IT3) -> 0.47 | NJ3: =IF($LX3="","",JM3) -> 0.44 | NK3: =IF($LX3="","",KF3) -> 0.43 | NL3: =IF($LX3="","",KY3) -> 0.46 | NM3: =MEDIAN(MX3:NL3) -> 0.46
