Workbook

Sheet LineStatsOnly
A1: G_Id | B1: G_Date | C1: G_H_Id | D1: HNAME | E1: G_V_Id | F1: VNAME | G1: H_Bookie_Bet_Price | H1: V_Bookie_Bet_Price | I1: LineStatsOnlyPosition | J1: LineStatsOnlyPlay | K1: Scion_Side_Play_Position | L1: Scion_H_ProbabilityEdge | M1: Scion_Side_Stars | N1: Scion_Side_Play_Confidence | O1: PlayByAgreement | P1: G_Bookie_TotalOver | Q1: G_PH_Win | R1: G_H_Runs | S1: G_V_Runs | T1: G_Actual_Runs_Diff | U1: Winning_Position | V1: WinBet? | W1: Invest | X1: Return | Y1: Proft | Z1: %ROI | AA1: Comments
A2: 824915 | B2: =VLOOKUP($A2,ScionOutput!$A$3:$BL$215,3,FALSE) -> 46179 | C2: =VLOOKUP($A2,ScionOutput!$A$3:$BL$215,22,FALSE) -> 0 | D2: =VLOOKUP($A2,ScionOutput!$A$3:$BL$215,23,FALSE) -> ATL | E2: =VLOOKUP($A2,ScionOutput!$A$3:$BL$215,6,FALSE) -> 22 | F2: =VLOOKUP($A2,ScionOutput!$A$3:$BL$215,7,FALSE) -> PIT | G2: =VLOOKUP($A2,ScionOutput!$A$3:$BL$215,26,FALSE) -> -110 | H2: =VLOOKUP($A2,ScionOutput!$A$3:$BL$215,10,FALSE) -> 100 | I2: =VLOOKUP($A2,ScionOutput!$A$3:$BL$215,45,FALSE) -> HomFave | J2: =VLOOKUP($A2,ScionOutput!$A$3:$BL$215,46,FALSE) -> 1 | K2: =VLOOKUP($A2,ScionOutput!$A$3:$BL$215,58,FALSE) -> HomFave | L2: =VLOOKUP($A2,ScionOutput!$A$3:$BL$215,59,FALSE) -> 0.01837 | M2: =VLOOKUP($A2,ScionOutput!$A$3:$BL$215,62,FALSE) -> 1 | N2: =VLOOKUP($A2,ScionOutput!$A$3:$BL$215,63,FALSE) -> 0.93 | O2: =ISNUMBER(SEARCH("Play determined by LineStatEns and StatOnlyEns agreement", AA2)) -> TRUE | P2: =VLOOKUP($A2,Outcomes!$B$3:$I$209,8,FALSE) -> 9 | Q2: =IF(R2>S2,1,IF(R2<S2,-1,0)) -> 1 | R2: =VLOOKUP($A2,Outcomes!$B$3:$I$209,5,FALSE) -> 6 | S2: =VLOOKUP($A2,Outcomes!$B$3:$I$209,6,FALSE) -> 3 | T2: =VLOOKUP($A2,Outcomes!$B$3:$I$209,7,FALSE) -> -3 | U2: =IF(T2=0,"Push",IF(G2<H2,IF(T2<0,"HomFave","VisDog"),IF(T2>0,"VisFave","HomDog"))) -> HomFave | V2: =IF(OR(T2=0,I2="No Play",J2<>1),"",IF(U2=I2,1,0)) -> 1 | W2: =IF(V2="","",IF(G2<H2,IF(K2="HomFave",ABS(G2),IF(H2<0,ABS(H2),100)),IF(K2="VisFave",ABS(H2),IF(G2<0,ABS(G2),100)))) -> 110 | X2: =IF(V2="","",IF(V2=0,0,IF(G2<H2,IF(K2="HomFave",W2+100,IF(H2<0,100+W2,W2+ABS(H2))),IF(K2="VisFave",W2+100,IF(G2<0,100+W2,W2+ABS(G2)))))) -> 210 | Y2: =IF(V2="","",X2-W2) -> 100 | Z2: =IF(V2="","",Y2/W2) -> 0.90909091 | AA2: =VLOOKUP($A2,ScionOutput!$A$3:$BL$215,64,FALSE) -> 824915. Play determined by LineStatEns and StatOnlyEns agreement.
A3: 825075 | B3: =VLOOKUP($A3,ScionOutput!$A$3:$BL$215,3,FALSE) -> 46179 | C3: =VLOOKUP($A3,ScionOutput!$A$3:$BL$215,22,FALSE) -> 1 | D3: =VLOOKUP($A3,ScionOutput!$A$3:$BL$215,23,FALSE) -> ARZ | E3: =VLOOKUP($A3,ScionOutput!$A$3:$BL$215,6,FALSE) -> 16 | F3: =VLOOKUP($A3,ScionOutput!$A$3:$BL$215,7,FALSE) -> WAS | G3: =VLOOKUP($A3,ScionOutput!$A$3:$BL$215,26,FALSE) -> -155 | H3: =VLOOKUP($A3,ScionOutput!$A$3:$BL$215,10,FALSE) -> 140 | I3: =VLOOKUP($A3,ScionOutput!$A$3:$BL$215,45,FALSE) -> HomFave | J3: =VLOOKUP($A3,ScionOutput!$A$3:$BL$215,46,FALSE) -> 0 | K3: =VLOOKUP($A3,ScionOutput!$A$3:$BL$215,58,FALSE) -> No Play | L3: =VLOOKUP($A3,ScionOutput!$A$3:$BL$215,59,FALSE) -> 0 | M3: =VLOOKUP($A3,ScionOutput!$A$3:$BL$215,62,FALSE) -> 0 | N3: =VLOOKUP($A3,ScionOutput!$A$3:$BL$215,63,FALSE) -> 0 | O3: =ISNUMBER(SEARCH("Play determined by LineStatEns and StatOnlyEns agreement", AA3)) -> FALSE | P3: =VLOOKUP($A3,Outcomes!$B$3:$I$209,8,FALSE) -> 7 | Q3: =IF(R3>S3,1,IF(R3<S3,-1,0)) -> -1 | R3: =VLOOKUP($A3,Outcomes!$B$3:$I$209,5,FALSE) -> 1 | S3: =VLOOKUP($A3,Outcomes!$B$3:$I$209,6,FALSE) -> 6 | T3: =VLOOKUP($A3,Outcomes!$B$3:$I$209,7,FALSE) -> 5 | U3: =IF(T3=0,"Push",IF(G3<H3,IF(T3<0,"HomFave","VisDog"),IF(T3>0,"VisFave","HomDog"))) -> VisDog | V3: =IF(OR(T3=0,I3="No Play",J3<>1),"",IF(U3=I3,1,0)) | W3: =IF(V3="","",IF(G3<H3,IF(K3="HomFave",ABS(G3),IF(H3<0,ABS(H3),100)),IF(K3="VisFave",ABS(H3),IF(G3<0,ABS(G3),100)))) | X3: =IF(V3="","",IF(V3=0,0,IF(G3<H3,IF(K3="HomFave",W3+100,IF(H3<0,100+W3,W3+ABS(H3))),IF(K3="VisFave",W3+100,IF(G3<0,100+W3,W3+ABS(G3)))))) | Y3: =IF(V3="","",X3-W3) | Z3: =IF(V3="","",Y3/W3) | AA3: =VLOOKUP($A3,ScionOutput!$A$3:$BL$215,64,FALSE) -> 825075. LineStatEns is NoPlay as bookie-line outside range. StatOnlyEns is NoPlay as bookie-line outside range. No play due to strategy constraints.
A4: 824669 | B4: =VLOOKUP($A4,ScionOutput!$A$3:$BL$215,3,FALSE) -> 46179 | C4: =VLOOKUP($A4,ScionOutput!$A$3:$BL$215,22,FALSE) -> 5 | D4: =VLOOKUP($A4,ScionOutput!$A$3:$BL$215,23,FALSE) -> CHC | E4: =VLOOKUP($A4,ScionOutput!$A$3:$BL$215,6,FALSE) -> 25 | F4: =VLOOKUP($A4,ScionOutput!$A$3:$BL$215,7,FALSE) -> SF | G4: =VLOOKUP($A4,ScionOutput!$A$3:$BL$215,26,FALSE) -> -140 | H4: =VLOOKUP($A4,ScionOutput!$A$3:$BL$215,10,FALSE) -> 127 | I4: =VLOOKUP($A4,ScionOutput!$A$3:$BL$215,45,FALSE) -> HomFave | J4: =VLOOKUP($A4,ScionOutput!$A$3:$BL$215,46,FALSE) -> 0 | K4: =VLOOKUP($A4,ScionOutput!$A$3:$BL$215,58,FALSE) -> No Play | L4: =VLOOKUP($A4,ScionOutput!$A$3:$BL$215,59,FALSE) -> 0 | M4: =VLOOKUP($A4,ScionOutput!$A$3:$BL$215,62,FALSE) -> 0 | N4: =VLOOKUP($A4,ScionOutput!$A$3:$BL$215,63,FALSE) -> 0 | O4: =ISNUMBER(SEARCH("Play determined by LineStatEns and StatOnlyEns agreement", AA4)) -> FALSE | P4: =VLOOKUP($A4,Outcomes!$B$3:$I$209,8,FALSE) -> 5 | Q4: =IF(R4>S4,1,IF(R4<S4,-1,0)) -> 1 | R4: =VLOOKUP($A4,Outcomes!$B$3:$I$209,5,FALSE) -> 3 | S4: =VLOOKUP($A4,Outcomes!$B$3:$I$209,6,FALSE) -> 2 | T4: =VLOOKUP($A4,Outcomes!$B$3:$I$209,7,FALSE) -> -1 | U4: =IF(T4=0,"Push",IF(G4<H4,IF(T4<0,"HomFave","VisDog"),IF(T4>0,"VisFave","HomDog"))) -> HomFave | V4: =IF(OR(T4=0,I4="No Play",J4<>1),"",IF(U4=I4,1,0)) | W4: =IF(V4="","",IF(G4<H4,IF(K4="HomFave",ABS(G4),IF(H4<0,ABS(H4),100)),IF(K4="VisFave",ABS(H4),IF(G4<0,ABS(G4),100)))) | X4: =IF(V4="","",IF(V4=0,0,IF(G4<H4,IF(K4="HomFave",W4+100,IF(H4<0,100+W4,W4+ABS(H4))),IF(K4="VisFave",W4+100,IF(G4<0,100+W4,W4+ABS(G4)))))) | Y4: =IF(V4="","",X4-W4) | Z4: =IF(V4="","",Y4/W4) | AA4: =VLOOKUP($A4,ScionOutput!$A$3:$BL$215,64,FALSE) -> 824669. LineStatEns probability points gap does not exceed threshold (no edge found)! StatOnlyEns probability points gap does not exceed threshold (no edge found)! No play due to strategy constraints.
A5: 824351 | B5: =VLOOKUP($A5,ScionOutput!$A$3:$BL$215,3,FALSE) -> 46179 | C5: =VLOOKUP($A5,ScionOutput!$A$3:$BL$215,22,FALSE) -> 8 | D5: =VLOOKUP($A5,ScionOutput!$A$3:$BL$215,23,FALSE) -> COL | E5: =VLOOKUP($A5,ScionOutput!$A$3:$BL$215,6,FALSE) -> 17 | F5: =VLOOKUP($A5,ScionOutput!$A$3:$BL$215,7,FALSE) -> MLW | G5: =VLOOKUP($A5,ScionOutput!$A$3:$BL$215,26,FALSE) -> 214 | H5: =VLOOKUP($A5,ScionOutput!$A$3:$BL$215,10,FALSE) -> -240 | I5: =VLOOKUP($A5,ScionOutput!$A$3:$BL$215,45,FALSE) -> VisFave | J5: =VLOOKUP($A5,ScionOutput!$A$3:$BL$215,46,FALSE) -> 0 | K5: =VLOOKUP($A5,ScionOutput!$A$3:$BL$215,58,FALSE) -> No Play | L5: =VLOOKUP($A5,ScionOutput!$A$3:$BL$215,59,FALSE) -> 0 | M5: =VLOOKUP($A5,ScionOutput!$A$3:$BL$215,62,FALSE) -> 0 | N5: =VLOOKUP($A5,ScionOutput!$A$3:$BL$215,63,FALSE) -> 0 | O5: =ISNUMBER(SEARCH("Play determined by LineStatEns and StatOnlyEns agreement", AA5)) -> FALSE | P5: =VLOOKUP($A5,Outcomes!$B$3:$I$209,8,FALSE) -> 8 | Q5: =IF(R5>S5,1,IF(R5<S5,-1,0)) -> -1 | R5: =VLOOKUP($A5,Outcomes!$B$3:$I$209,5,FALSE) -> 1 | S5: =VLOOKUP($A5,Outcomes!$B$3:$I$209,6,FALSE) -> 7 | T5: =VLOOKUP($A5,Outcomes!$B$3:$I$209,7,FALSE) -> 6 | U5: =IF(T5=0,"Push",IF(G5<H5,IF(T5<0,"HomFave","VisDog"),IF(T5>0,"VisFave","HomDog"))) -> VisFave | V5: =IF(OR(T5=0,I5="No Play",J5<>1),"",IF(U5=I5,1,0)) | W5: =IF(V5="","",IF(G5<H5,IF(K5="HomFave",ABS(G5),IF(H5<0,ABS(H5),100)),IF(K5="VisFave",ABS(H5),IF(G5<0,ABS(G5),100)))) | X5: =IF(V5="","",IF(V5=0,0,IF(G5<H5,IF(K5="HomFave",W5+100,IF(H5<0,100+W5,W5+ABS(H5))),IF(K5="VisFave",W5+100,IF(G5<0,100+W5,W5+ABS(G5)))))) | Y5: =IF(V5="","",X5-W5) | Z5: =IF(V5="","",Y5/W5) | AA5: =VLOOKUP($A5,ScionOutput!$A$3:$BL$215,64,FALSE) -> 824351. LineStatEns is NoPlay as bookie-line outside range. StatOnlyEns is NoPlay as bookie-line outside range. No play due to strategy constraints.
A6: 824269 | B6: =VLOOKUP($A6,ScionOutput!$A$3:$BL$215,3,FALSE) -> 46179 | C6: =VLOOKUP($A6,ScionOutput!$A$3:$BL$215,22,FALSE) -> 10 | D6: =VLOOKUP($A6,ScionOutput!$A$3:$BL$215,23,FALSE) -> DET | E6: =VLOOKUP($A6,ScionOutput!$A$3:$BL$215,6,FALSE) -> 24 | F6: =VLOOKUP($A6,ScionOutput!$A$3:$BL$215,7,FALSE) -> SEA | G6: =VLOOKUP($A6,ScionOutput!$A$3:$BL$215,26,FALSE) -> 116 | H6: =VLOOKUP($A6,ScionOutput!$A$3:$BL$215,10,FALSE) -> -128 | I6: =VLOOKUP($A6,ScionOutput!$A$3:$BL$215,45,FALSE) -> VisFave | J6: =VLOOKUP($A6,ScionOutput!$A$3:$BL$215,46,FALSE) -> 0 | K6: =VLOOKUP($A6,ScionOutput!$A$3:$BL$215,58,FALSE) -> No Play | L6: =VLOOKUP($A6,ScionOutput!$A$3:$BL$215,59,FALSE) -> 0 | M6: =VLOOKUP($A6,ScionOutput!$A$3:$BL$215,62,FALSE) -> 0 | N6: =VLOOKUP($A6,ScionOutput!$A$3:$BL$215,63,FALSE) -> 0 | O6: =ISNUMBER(SEARCH("Play determined by LineStatEns and StatOnlyEns agreement", AA6)) -> FALSE | P6: =VLOOKUP($A6,Outcomes!$B$3:$I$209,8,FALSE) -> 4 | Q6: =IF(R6>S6,1,IF(R6<S6,-1,0)) -> -1 | R6: =VLOOKUP($A6,Outcomes!$B$3:$I$209,5,FALSE) -> 0 | S6: =VLOOKUP($A6,Outcomes!$B$3:$I$209,6,FALSE) -> 4 | T6: =VLOOKUP($A6,Outcomes!$B$3:$I$209,7,FALSE) -> 4 | U6: =IF(T6=0,"Push",IF(G6<H6,IF(T6<0,"HomFave","VisDog"),IF(T6>0,"VisFave","HomDog"))) -> VisFave | V6: =IF(OR(T6=0,I6="No Play",J6<>1),"",IF(U6=I6,1,0)) | W6: =IF(V6="","",IF(G6<H6,IF(K6="HomFave",ABS(G6),IF(H6<0,ABS(H6),100)),IF(K6="VisFave",ABS(H6),IF(G6<0,ABS(G6),100)))) | X6: =IF(V6="","",IF(V6=0,0,IF(G6<H6,IF(K6="HomFave",W6+100,IF(H6<0,100+W6,W6+ABS(H6))),IF(K6="VisFave",W6+100,IF(G6<0,100+W6,W6+ABS(G6)))))) | Y6: =IF(V6="","",X6-W6) | Z6: =IF(V6="","",Y6/W6) | AA6: =VLOOKUP($A6,ScionOutput!$A$3:$BL$215,64,FALSE) -> 824269. VF plays are disallowed. No play due to strategy constraints.
A7: 823859 | B7: =VLOOKUP($A7,ScionOutput!$A$3:$BL$215,3,FALSE) -> 46179 | C7: =VLOOKUP($A7,ScionOutput!$A$3:$BL$215,22,FALSE) -> 11 | D7: =VLOOKUP($A7,ScionOutput!$A$3:$BL$215,23,FALSE) -> FLO | E7: =VLOOKUP($A7,ScionOutput!$A$3:$BL$215,6,FALSE) -> 27 | F7: =VLOOKUP($A7,ScionOutput!$A$3:$BL$215,7,FALSE) -> TB | G7: =VLOOKUP($A7,ScionOutput!$A$3:$BL$215,26,FALSE) -> 117 | H7: =VLOOKUP($A7,ScionOutput!$A$3:$BL$215,10,FALSE) -> -129 | I7: =VLOOKUP($A7,ScionOutput!$A$3:$BL$215,45,FALSE) -> VisFave | J7: =VLOOKUP($A7,ScionOutput!$A$3:$BL$215,46,FALSE) -> 0 | K7: =VLOOKUP($A7,ScionOutput!$A$3:$BL$215,58,FALSE) -> No Play | L7: =VLOOKUP($A7,ScionOutput!$A$3:$BL$215,59,FALSE) -> 0 | M7: =VLOOKUP($A7,ScionOutput!$A$3:$BL$215,62,FALSE) -> 0 | N7: =VLOOKUP($A7,ScionOutput!$A$3:$BL$215,63,FALSE) -> 0 | O7: =ISNUMBER(SEARCH("Play determined by LineStatEns and StatOnlyEns agreement", AA7)) -> FALSE | P7: =VLOOKUP($A7,Outcomes!$B$3:$I$209,8,FALSE) -> 7 | Q7: =IF(R7>S7,1,IF(R7<S7,-1,0)) -> 1 | R7: =VLOOKUP($A7,Outcomes!$B$3:$I$209,5,FALSE) -> 4 | S7: =VLOOKUP($A7,Outcomes!$B$3:$I$209,6,FALSE) -> 3 | T7: =VLOOKUP($A7,Outcomes!$B$3:$I$209,7,FALSE) -> -1 | U7: =IF(T7=0,"Push",IF(G7<H7,IF(T7<0,"HomFave","VisDog"),IF(T7>0,"VisFave","HomDog"))) -> HomDog | V7: =IF(OR(T7=0,I7="No Play",J7<>1),"",IF(U7=I7,1,0)) | W7: =IF(V7="","",IF(G7<H7,IF(K7="HomFave",ABS(G7),IF(H7<0,ABS(H7),100)),IF(K7="VisFave",ABS(H7),IF(G7<0,ABS(G7),100)))) | X7: =IF(V7="","",IF(V7=0,0,IF(G7<H7,IF(K7="HomFave",W7+100,IF(H7<0,100+W7,W7+ABS(H7))),IF(K7="VisFave",W7+100,IF(G7<0,100+W7,W7+ABS(G7)))))) | Y7: =IF(V7="","",X7-W7) | Z7: =IF(V7="","",Y7/W7) | AA7: =VLOOKUP($A7,ScionOutput!$A$3:$BL$215,64,FALSE) -> 823859. VF plays are disallowed. No play due to strategy constraints.
A8: 824184 | B8: =VLOOKUP($A8,ScionOutput!$A$3:$BL$215,3,FALSE) -> 46179 | C8: =VLOOKUP($A8,ScionOutput!$A$3:$BL$215,22,FALSE) -> 12 | D8: =VLOOKUP($A8,ScionOutput!$A$3:$BL$215,23,FALSE) -> HOU | E8: =VLOOKUP($A8,ScionOutput!$A$3:$BL$215,6,FALSE) -> 20 | F8: =VLOOKUP($A8,ScionOutput!$A$3:$BL$215,7,FALSE) -> OAK | G8: =VLOOKUP($A8,ScionOutput!$A$3:$BL$215,26,FALSE) -> -107 | H8: =VLOOKUP($A8,ScionOutput!$A$3:$BL$215,10,FALSE) -> -103 | I8: =VLOOKUP($A8,ScionOutput!$A$3:$BL$215,45,FALSE) -> VisDog | J8: =VLOOKUP($A8,ScionOutput!$A$3:$BL$215,46,FALSE) -> 0 | K8: =VLOOKUP($A8,ScionOutput!$A$3:$BL$215,58,FALSE) -> No Play | L8: =VLOOKUP($A8,ScionOutput!$A$3:$BL$215,59,FALSE) -> 0 | M8: =VLOOKUP($A8,ScionOutput!$A$3:$BL$215,62,FALSE) -> 0 | N8: =VLOOKUP($A8,ScionOutput!$A$3:$BL$215,63,FALSE) -> 0 | O8: =ISNUMBER(SEARCH("Play determined by LineStatEns and StatOnlyEns agreement", AA8)) -> FALSE | P8: =VLOOKUP($A8,Outcomes!$B$3:$I$209,8,FALSE) -> 15 | Q8: =IF(R8>S8,1,IF(R8<S8,-1,0)) -> 1 | R8: =VLOOKUP($A8,Outcomes!$B$3:$I$209,5,FALSE) -> 13 | S8: =VLOOKUP($A8,Outcomes!$B$3:$I$209,6,FALSE) -> 2 | T8: =VLOOKUP($A8,Outcomes!$B$3:$I$209,7,FALSE) -> -11 | U8: =IF(T8=0,"Push",IF(G8<H8,IF(T8<0,"HomFave","VisDog"),IF(T8>0,"VisFave","HomDog"))) -> HomFave | V8: =IF(OR(T8=0,I8="No Play",J8<>1),"",IF(U8=I8,1,0)) | W8: =IF(V8="","",IF(G8<H8,IF(K8="HomFave",ABS(G8),IF(H8<0,ABS(H8),100)),IF(K8="VisFave",ABS(H8),IF(G8<0,ABS(G8),100)))) | X8: =IF(V8="","",IF(V8=0,0,IF(G8<H8,IF(K8="HomFave",W8+100,IF(H8<0,100+W8,W8+ABS(H8))),IF(K8="VisFave",W8+100,IF(G8<0,100+W8,W8+ABS(G8)))))) | Y8: =IF(V8="","",X8-W8) | Z8: =IF(V8="","",Y8/W8) | AA8: =VLOOKUP($A8,ScionOutput!$A$3:$BL$215,64,FALSE) -> 824184. V_SP is Null, team-based avg used. NoPlay as V_SP is Null.
A9: 823942 | B9: =VLOOKUP($A9,ScionOutput!$A$3:$BL$215,3,FALSE) -> 46179 | C9: =VLOOKUP($A9,ScionOutput!$A$3:$BL$215,22,FALSE) -> 14 | D9: =VLOOKUP($A9,ScionOutput!$A$3:$BL$215,23,FALSE) -> LA | E9: =VLOOKUP($A9,ScionOutput!$A$3:$BL$215,6,FALSE) -> 4 | F9: =VLOOKUP($A9,ScionOutput!$A$3:$BL$215,7,FALSE) -> LAA | G9: =VLOOKUP($A9,ScionOutput!$A$3:$BL$215,26,FALSE) -> -312 | H9: =VLOOKUP($A9,ScionOutput!$A$3:$BL$215,10,FALSE) -> 275 | I9: =VLOOKUP($A9,ScionOutput!$A$3:$BL$215,45,FALSE) -> HomFave | J9: =VLOOKUP($A9,ScionOutput!$A$3:$BL$215,46,FALSE) -> 0 | K9: =VLOOKUP($A9,ScionOutput!$A$3:$BL$215,58,FALSE) -> No Play | L9: =VLOOKUP($A9,ScionOutput!$A$3:$BL$215,59,FALSE) -> 0 | M9: =VLOOKUP($A9,ScionOutput!$A$3:$BL$215,62,FALSE) -> 0 | N9: =VLOOKUP($A9,ScionOutput!$A$3:$BL$215,63,FALSE) -> 0 | O9: =ISNUMBER(SEARCH("Play determined by LineStatEns and StatOnlyEns agreement", AA9)) -> FALSE | P9: =VLOOKUP($A9,Outcomes!$B$3:$I$209,8,FALSE) -> 11 | Q9: =IF(R9>S9,1,IF(R9<S9,-1,0)) -> 1 | R9: =VLOOKUP($A9,Outcomes!$B$3:$I$209,5,FALSE) -> 9 | S9: =VLOOKUP($A9,Outcomes!$B$3:$I$209,6,FALSE) -> 2 | T9: =VLOOKUP($A9,Outcomes!$B$3:$I$209,7,FALSE) -> -7 | U9: =IF(T9=0,"Push",IF(G9<H9,IF(T9<0,"HomFave","VisDog"),IF(T9>0,"VisFave","HomDog"))) -> HomFave | V9: =IF(OR(T9=0,I9="No Play",J9<>1),"",IF(U9=I9,1,0)) | W9: =IF(V9="","",IF(G9<H9,IF(K9="HomFave",ABS(G9),IF(H9<0,ABS(H9),100)),IF(K9="VisFave",ABS(H9),IF(G9<0,ABS(G9),100)))) | X9: =IF(V9="","",IF(V9=0,0,IF(G9<H9,IF(K9="HomFave",W9+100,IF(H9<0,100+W9,W9+ABS(H9))),IF(K9="VisFave",W9+100,IF(G9<0,100+W9,W9+ABS(G9)))))) | Y9: =IF(V9="","",X9-W9) | Z9: =IF(V9="","",Y9/W9) | AA9: =VLOOKUP($A9,ScionOutput!$A$3:$BL$215,64,FALSE) -> 823942. LineStatEns is NoPlay as bookie-line outside range. StatOnlyEns is NoPlay as bookie-line outside range. No play due to strategy constraints.
A10: 823697 | B10: =VLOOKUP($A10,ScionOutput!$A$3:$BL$215,3,FALSE) -> 46179 | C10: =VLOOKUP($A10,ScionOutput!$A$3:$BL$215,22,FALSE) -> 15 | D10: =VLOOKUP($A10,ScionOutput!$A$3:$BL$215,23,FALSE) -> MIN | E10: =VLOOKUP($A10,ScionOutput!$A$3:$BL$215,6,FALSE) -> 13 | F10: =VLOOKUP($A10,ScionOutput!$A$3:$BL$215,7,FALSE) -> KC | G10: =VLOOKUP($A10,ScionOutput!$A$3:$BL$215,26,FALSE) -> -145 | H10: =VLOOKUP($A10,ScionOutput!$A$3:$BL$215,10,FALSE) -> 131 | I10: =VLOOKUP($A10,ScionOutput!$A$3:$BL$215,45,FALSE) -> HomFave | J10: =VLOOKUP($A10,ScionOutput!$A$3:$BL$215,46,FALSE) -> 0 | K10: =VLOOKUP($A10,ScionOutput!$A$3:$BL$215,58,FALSE) -> No Play | L10: =VLOOKUP($A10,ScionOutput!$A$3:$BL$215,59,FALSE) -> 0 | M10: =VLOOKUP($A10,ScionOutput!$A$3:$BL$215,62,FALSE) -> 0 | N10: =VLOOKUP($A10,ScionOutput!$A$3:$BL$215,63,FALSE) -> 0 | O10: =ISNUMBER(SEARCH("Play determined by LineStatEns and StatOnlyEns agreement", AA10)) -> FALSE | P10: =VLOOKUP($A10,Outcomes!$B$3:$I$209,8,FALSE) -> 5 | Q10: =IF(R10>S10,1,IF(R10<S10,-1,0)) -> -1 | R10: =VLOOKUP($A10,Outcomes!$B$3:$I$209,5,FALSE) -> 2 | S10: =VLOOKUP($A10,Outcomes!$B$3:$I$209,6,FALSE) -> 3 | T10: =VLOOKUP($A10,Outcomes!$B$3:$I$209,7,FALSE) -> 1 | U10: =IF(T10=0,"Push",IF(G10<H10,IF(T10<0,"HomFave","VisDog"),IF(T10>0,"VisFave","HomDog"))) -> VisDog | V10: =IF(OR(T10=0,I10="No Play",J10<>1),"",IF(U10=I10,1,0)) | W10: =IF(V10="","",IF(G10<H10,IF(K10="HomFave",ABS(G10),IF(H10<0,ABS(H10),100)),IF(K10="VisFave",ABS(H10),IF(G10<0,ABS(G10),100)))) | X10: =IF(V10="","",IF(V10=0,0,IF(G10<H10,IF(K10="HomFave",W10+100,IF(H10<0,100+W10,W10+ABS(H10))),IF(K10="VisFave",W10+100,IF(G10<0,100+W10,W10+ABS(G10)))))) | Y10: =IF(V10="","",X10-W10) | Z10: =IF(V10="","",Y10/W10) | AA10: =VLOOKUP($A10,ScionOutput!$A$3:$BL$215,64,FALSE) -> 823697. LineStatEns probability points gap does not exceed threshold (no edge found)! StatOnlyEns probability points gap does not exceed threshold (no edge found)! No play due to strategy constraints.
A11: 823454 | B11: =VLOOKUP($A11,ScionOutput!$A$3:$BL$215,3,FALSE) -> 46179 | C11: =VLOOKUP($A11,ScionOutput!$A$3:$BL$215,22,FALSE) -> 21 | D11: =VLOOKUP($A11,ScionOutput!$A$3:$BL$215,23,FALSE) -> PHI | E11: =VLOOKUP($A11,ScionOutput!$A$3:$BL$215,6,FALSE) -> 9 | F11: =VLOOKUP($A11,ScionOutput!$A$3:$BL$215,7,FALSE) -> CWS | G11: =VLOOKUP($A11,ScionOutput!$A$3:$BL$215,26,FALSE) -> -123 | H11: =VLOOKUP($A11,ScionOutput!$A$3:$BL$215,10,FALSE) -> 112 | I11: =VLOOKUP($A11,ScionOutput!$A$3:$BL$215,45,FALSE) -> HomFave | J11: =VLOOKUP($A11,ScionOutput!$A$3:$BL$215,46,FALSE) -> 0 | K11: =VLOOKUP($A11,ScionOutput!$A$3:$BL$215,58,FALSE) -> No Play | L11: =VLOOKUP($A11,ScionOutput!$A$3:$BL$215,59,FALSE) -> 0 | M11: =VLOOKUP($A11,ScionOutput!$A$3:$BL$215,62,FALSE) -> 0 | N11: =VLOOKUP($A11,ScionOutput!$A$3:$BL$215,63,FALSE) -> 0 | O11: =ISNUMBER(SEARCH("Play determined by LineStatEns and StatOnlyEns agreement", AA11)) -> FALSE | P11: =VLOOKUP($A11,Outcomes!$B$3:$I$209,8,FALSE) -> 9 | Q11: =IF(R11>S11,1,IF(R11<S11,-1,0)) -> -1 | R11: =VLOOKUP($A11,Outcomes!$B$3:$I$209,5,FALSE) -> 3 | S11: =VLOOKUP($A11,Outcomes!$B$3:$I$209,6,FALSE) -> 6 | T11: =VLOOKUP($A11,Outcomes!$B$3:$I$209,7,FALSE) -> 3 | U11: =IF(T11=0,"Push",IF(G11<H11,IF(T11<0,"HomFave","VisDog"),IF(T11>0,"VisFave","HomDog"))) -> VisDog | V11: =IF(OR(T11=0,I11="No Play",J11<>1),"",IF(U11=I11,1,0)) | W11: =IF(V11="","",IF(G11<H11,IF(K11="HomFave",ABS(G11),IF(H11<0,ABS(H11),100)),IF(K11="VisFave",ABS(H11),IF(G11<0,ABS(G11),100)))) | X11: =IF(V11="","",IF(V11=0,0,IF(G11<H11,IF(K11="HomFave",W11+100,IF(H11<0,100+W11,W11+ABS(H11))),IF(K11="VisFave",W11+100,IF(G11<0,100+W11,W11+ABS(G11)))))) | Y11: =IF(V11="","",X11-W11) | Z11: =IF(V11="","",Y11/W11) | AA11: =VLOOKUP($A11,ScionOutput!$A$3:$BL$215,64,FALSE) -> 823454. LineStatEns probability points gap does not exceed threshold (no edge found)! No play due to strategy constraints.
A12: 823292 | B12: =VLOOKUP($A12,ScionOutput!$A$3:$BL$215,3,FALSE) -> 46179 | C12: =VLOOKUP($A12,ScionOutput!$A$3:$BL$215,22,FALSE) -> 23 | D12: =VLOOKUP($A12,ScionOutput!$A$3:$BL$215,23,FALSE) -> SD | E12: =VLOOKUP($A12,ScionOutput!$A$3:$BL$215,6,FALSE) -> 18 | F12: =VLOOKUP($A12,ScionOutput!$A$3:$BL$215,7,FALSE) -> NYM | G12: =VLOOKUP($A12,ScionOutput!$A$3:$BL$215,26,FALSE) -> 104 | H12: =VLOOKUP($A12,ScionOutput!$A$3:$BL$215,10,FALSE) -> -115 | I12: =VLOOKUP($A12,ScionOutput!$A$3:$BL$215,45,FALSE) -> VisFave | J12: =VLOOKUP($A12,ScionOutput!$A$3:$BL$215,46,FALSE) -> 0 | K12: =VLOOKUP($A12,ScionOutput!$A$3:$BL$215,58,FALSE) -> No Play | L12: =VLOOKUP($A12,ScionOutput!$A$3:$BL$215,59,FALSE) -> 0 | M12: =VLOOKUP($A12,ScionOutput!$A$3:$BL$215,62,FALSE) -> 0 | N12: =VLOOKUP($A12,ScionOutput!$A$3:$BL$215,63,FALSE) -> 0 | O12: =ISNUMBER(SEARCH("Play determined by LineStatEns and StatOnlyEns agreement", AA12)) -> FALSE | P12: =VLOOKUP($A12,Outcomes!$B$3:$I$209,8,FALSE) -> 5 | Q12: =IF(R12>S12,1,IF(R12<S12,-1,0)) -> 1 | R12: =VLOOKUP($A12,Outcomes!$B$3:$I$209,5,FALSE) -> 3 | S12: =VLOOKUP($A12,Outcomes!$B$3:$I$209,6,FALSE) -> 2 | T12: =VLOOKUP($A12,Outcomes!$B$3:$I$209,7,FALSE) -> -1 | U12: =IF(T12=0,"Push",IF(G12<H12,IF(T12<0,"HomFave","VisDog"),IF(T12>0,"VisFave","HomDog"))) -> HomDog | V12: =IF(OR(T12=0,I12="No Play",J12<>1),"",IF(U12=I12,1,0)) | W12: =IF(V12="","",IF(G12<H12,IF(K12="HomFave",ABS(G12),IF(H12<0,ABS(H12),100)),IF(K12="VisFave",ABS(H12),IF(G12<0,ABS(G12),100)))) | X12: =IF(V12="","",IF(V12=0,0,IF(G12<H12,IF(K12="HomFave",W12+100,IF(H12<0,100+W12,W12+ABS(H12))),IF(K12="VisFave",W12+100,IF(G12<0,100+W12,W12+ABS(G12)))))) | Y12: =IF(V12="","",X12-W12) | Z12: =IF(V12="","",Y12/W12) | AA12: =VLOOKUP($A12,ScionOutput!$A$3:$BL$215,64,FALSE) -> 823292. VF plays are disallowed. No play due to strategy constraints.
A13: 823048 | B13: =VLOOKUP($A13,ScionOutput!$A$3:$BL$215,3,FALSE) -> 46179 | C13: =VLOOKUP($A13,ScionOutput!$A$3:$BL$215,22,FALSE) -> 26 | D13: =VLOOKUP($A13,ScionOutput!$A$3:$BL$215,23,FALSE) -> STL | E13: =VLOOKUP($A13,ScionOutput!$A$3:$BL$215,6,FALSE) -> 6 | F13: =VLOOKUP($A13,ScionOutput!$A$3:$BL$215,7,FALSE) -> CIN | G13: =VLOOKUP($A13,ScionOutput!$A$3:$BL$215,26,FALSE) -> -125 | H13: =VLOOKUP($A13,ScionOutput!$A$3:$BL$215,10,FALSE) -> 113 | I13: =VLOOKUP($A13,ScionOutput!$A$3:$BL$215,45,FALSE) -> HomFave | J13: =VLOOKUP($A13,ScionOutput!$A$3:$BL$215,46,FALSE) -> 0 | K13: =VLOOKUP($A13,ScionOutput!$A$3:$BL$215,58,FALSE) -> No Play | L13: =VLOOKUP($A13,ScionOutput!$A$3:$BL$215,59,FALSE) -> 0 | M13: =VLOOKUP($A13,ScionOutput!$A$3:$BL$215,62,FALSE) -> 0 | N13: =VLOOKUP($A13,ScionOutput!$A$3:$BL$215,63,FALSE) -> 0 | O13: =ISNUMBER(SEARCH("Play determined by LineStatEns and StatOnlyEns agreement", AA13)) -> FALSE | P13: =VLOOKUP($A13,Outcomes!$B$3:$I$209,8,FALSE) -> 11 | Q13: =IF(R13>S13,1,IF(R13<S13,-1,0)) -> 1 | R13: =VLOOKUP($A13,Outcomes!$B$3:$I$209,5,FALSE) -> 6 | S13: =VLOOKUP($A13,Outcomes!$B$3:$I$209,6,FALSE) -> 5 | T13: =VLOOKUP($A13,Outcomes!$B$3:$I$209,7,FALSE) -> -1 | U13: =IF(T13=0,"Push",IF(G13<H13,IF(T13<0,"HomFave","VisDog"),IF(T13>0,"VisFave","HomDog"))) -> HomFave | V13: =IF(OR(T13=0,I13="No Play",J13<>1),"",IF(U13=I13,1,0)) | W13: =IF(V13="","",IF(G13<H13,IF(K13="HomFave",ABS(G13),IF(H13<0,ABS(H13),100)),IF(K13="VisFave",ABS(H13),IF(G13<0,ABS(G13),100)))) | X13: =IF(V13="","",IF(V13=0,0,IF(G13<H13,IF(K13="HomFave",W13+100,IF(H13<0,100+W13,W13+ABS(H13))),IF(K13="VisFave",W13+100,IF(G13<0,100+W13,W13+ABS(G13)))))) | Y13: =IF(V13="","",X13-W13) | Z13: =IF(V13="","",Y13/W13) | AA13: =VLOOKUP($A13,ScionOutput!$A$3:$BL$215,64,FALSE) -> 823048. LineStatEns probability points gap does not exceed threshold (no edge found)! StatOnlyEns probability points gap does not exceed threshold (no edge found)! No play due to strategy constraints.
... A209: 822883 | B209: =VLOOKUP($A209,ScionOutput!$A$3:$BL$215,3,FALSE) -> 46194 | C209: =VLOOKUP($A209,ScionOutput!$A$3:$BL$215,22,FALSE) -> 28 | D209: =VLOOKUP($A209,ScionOutput!$A$3:$BL$215,23,FALSE) -> TEX | E209: =VLOOKUP($A209,ScionOutput!$A$3:$BL$215,6,FALSE) -> 23 | F209: =VLOOKUP($A209,ScionOutput!$A$3:$BL$215,7,FALSE) -> SD | G209: =VLOOKUP($A209,ScionOutput!$A$3:$BL$215,26,FALSE) -> -160 | H209: =VLOOKUP($A209,ScionOutput!$A$3:$BL$215,10,FALSE) -> 147 | I209: =VLOOKUP($A209,ScionOutput!$A$3:$BL$215,45,FALSE) -> HomFave | J209: =VLOOKUP($A209,ScionOutput!$A$3:$BL$215,46,FALSE) -> 0 | K209: =VLOOKUP($A209,ScionOutput!$A$3:$BL$215,58,FALSE) -> No Play | L209: =VLOOKUP($A209,ScionOutput!$A$3:$BL$215,59,FALSE) -> 0 | M209: =VLOOKUP($A209,ScionOutput!$A$3:$BL$215,62,FALSE) -> 0 | N209: =VLOOKUP($A209,ScionOutput!$A$3:$BL$215,63,FALSE) -> 0 | O209: =ISNUMBER(SEARCH("Play determined by LineStatEns and StatOnlyEns agreement", AA209)) -> FALSE | P209: =VLOOKUP($A209,Outcomes!$B$3:$I$209,8,FALSE) -> 7 | Q209: =IF(R209>S209,1,IF(R209<S209,-1,0)) -> 1 | R209: =VLOOKUP($A209,Outcomes!$B$3:$I$209,5,FALSE) -> 4 | S209: =VLOOKUP($A209,Outcomes!$B$3:$I$209,6,FALSE) -> 3 | T209: =VLOOKUP($A209,Outcomes!$B$3:$I$209,7,FALSE) -> -1 | U209: =IF(T209=0,"Push",IF(G209<H209,IF(T209<0,"HomFave","VisDog"),IF(T209>0,"VisFave","HomDog"))) -> HomFave | V209: =IF(OR(T209=0,I209="No Play",J209<>1),"",IF(U209=I209,1,0)) | W209: =IF(V209="","",IF(G209<H209,IF(K209="HomFave",ABS(G209),IF(H209<0,ABS(H209),100)),IF(K209="VisFave",ABS(H209),IF(G209<0,ABS(G209),100)))) | X209: =IF(V209="","",IF(V209=0,0,IF(G209<H209,IF(K209="HomFave",W209+100,IF(H209<0,100+W209,W209+ABS(H209))),IF(K209="VisFave",W209+100,IF(G209<0,100+W209,W209+ABS(G209)))))) | Y209: =IF(V209="","",X209-W209) | Z209: =IF(V209="","",Y209/W209) | AA209: =VLOOKUP($A209,ScionOutput!$A$3:$BL$215,64,FALSE) -> 822883. LineStatEns is NoPlay as bookie-line outside range. StatOnlyEns is NoPlay as bookie-line outside range. No play due to strategy constraints.
D210: x | F210: x | G210: x | H210: x | I210: x | J210: x | K210: x | L210: x | M210: x | N210: x | O210: x | V210: x | W210: =SUM(W2:W209) -> 3606 | X210: =SUM(X2:X209) -> 3100 | Y210: =SUM(Y2:Y209) -> -506 | Z210: =IF(V210="","",Y210/W210) -> -0.14032169 | AA210: x
U211: #Games | V211: =COUNT(T2:T209) -> 208
U212: #Plays | V212: =COUNT(V2:V209) -> 34
U213: %Games | V213: =V212/V211 -> 0.16346154
U214: #Win | V214: =SUM(V2:V209) -> 15
U215: %WinRate | V215: =V214/V212 -> 0.44117647
U216: invest | V216: =W210 -> 3606
U217: return | V217: =X210 -> 3100
U218: profit | V218: =Y210 -> -506
U219: %ROI | V219: =IF(V216=0,0,V218/V216) -> -0.14032169
T221: HF | U221: plays | V221: =COUNTIFS($K$2:$K$209,"HomFave",$V$2:$V$209,"1")+COUNTIFS($K$2:$K$209,"HomFave",$V$2:$V$209,"0") -> 14 | X221: VD | Y221: plays | Z221: =COUNTIFS($K$2:$K$209,"VisDog",$V$2:$V$209,"1")+COUNTIFS($K$2:$K$209,"VisDog",$V$2:$V$209,"0") -> 16
U222: wins | V222: =COUNTIFS($K$2:$K$209,"HomFave",$V$2:$V$209,"1") -> 7 | Y222: wins | Z222: =COUNTIFS($K$2:$K$209,"VisDog",$V$2:$V$209,"1") -> 7
U223: %WR | V223: =IF(V221=0,0,V222/V221) -> 0.5 | Y223: %WR | Z223: =IF(Z221=0,0,Z222/Z221) -> 0.4375
U224: invest | V224: =SUMIFS($W$2:$W$209,$K$2:$K$209,"HomFave") -> 1593 | Y224: invest | Z224: =SUMIFS($W$2:$W$209,$K$2:$K$209,"VisDog") -> 1610
U225: return | V225: =SUMIFS($X$2:$X$209,$K$2:$K$209,"HomFave") -> 1467 | Y225: return | Z225: =SUMIFS($X$2:$X$209,$K$2:$K$209,"VisDog") -> 1431
U226: profit | V226: =V225-V224 -> -126 | Y226: profit | Z226: =Z225-Z224 -> -179
U227: %ROI | V227: =IF(V224=0,0,V226/V224) -> -0.079096045 | Y227: %ROI | Z227: =IF(Z224=0,0,Z226/Z224) -> -0.11118012
T229: VF | U229: plays | V229: =COUNTIFS($K$2:$K$209,"VisFave",$V$2:$V$209,"1")+COUNTIFS($K$2:$K$209,"VisFave",$V$2:$V$209,"0") -> 0 | X229: HD | Y229: plays | Z229: =COUNTIFS($K$2:$K$209,"HomDog",$V$2:$V$209,"1")+COUNTIFS($K$2:$K$209,"HomDog",$V$2:$V$209,"0") -> 4
U230: wins | V230: =COUNTIFS($K$2:$K$209,"VisFave",$V$2:$V$209,"1") -> 0 | Y230: wins | Z230: =COUNTIFS($K$2:$K$209,"HomDog",$V$2:$V$209,"1") -> 1
U231: %WR | V231: =IF(V229=0,0,V230/V229) -> 0 | Y231: %WR | Z231: =IF(Z229=0,0,Z230/Z229) -> 0.25
U232: invest | V232: =SUMIFS($W$2:$W$209,$K$2:$K$209,"VisFave") -> 0 | Y232: invest | Z232: =SUMIFS($W$2:$W$209,$K$2:$K$209,"HomDog") -> 403
U233: return | V233: =SUMIFS($X$2:$X$209,$K$2:$K$209,"VisFave") -> 0 | Y233: return | Z233: =SUMIFS($X$2:$X$209,$K$2:$K$209,"HomDog") -> 202
U234: profit | V234: =V233-V232 -> 0 | Y234: profit | Z234: =Z233-Z232 -> -201
U235: %ROI | V235: =IF(V232=0,0,V234/V232) -> 0 | Y235: %ROI | Z235: =IF(Z232=0,0,Z234/Z232) -> -0.49875931

Sheet StatsOnly
A1: G_Id | B1: G_Date | C1: G_H_Id | D1: HNAME | E1: G_V_Id | F1: VNAME | G1: H_Bookie_Bet_Price | H1: V_Bookie_Bet_Price | I1: StatsOnlyPosition | J1: StatsOnlyPlay | K1: Scion_Side_Play_Position | L1: Scion_H_ProbabilityEdge | M1: Scion_Side_Stars | N1: Scion_Side_Play_Confidence | O1: PlayByAgreement | P1: G_Bookie_TotalOver | Q1: G_PH_Win | R1: G_H_Runs | S1: G_V_Runs | T1: G_Actual_Runs_Diff | U1: Winning_Position | V1: WinBet? | W1: Invest | X1: Return | Y1: Proft | Z1: %ROI | AA1: Comments
A2: 824915 | B2: =VLOOKUP($A2,ScionOutput!$A$3:$BL$215,3,FALSE) -> 46179 | C2: =VLOOKUP($A2,ScionOutput!$A$3:$BL$215,22,FALSE) -> 0 | D2: =VLOOKUP($A2,ScionOutput!$A$3:$BL$215,23,FALSE) -> ATL | E2: =VLOOKUP($A2,ScionOutput!$A$3:$BL$215,6,FALSE) -> 22 | F2: =VLOOKUP($A2,ScionOutput!$A$3:$BL$215,7,FALSE) -> PIT | G2: =VLOOKUP($A2,ScionOutput!$A$3:$BL$215,26,FALSE) -> -110 | H2: =VLOOKUP($A2,ScionOutput!$A$3:$BL$215,10,FALSE) -> 100 | I2: =VLOOKUP($A2,ScionOutput!$A$3:$BL$215,55,FALSE) -> HomFave | J2: =VLOOKUP($A2,ScionOutput!$A$3:$BL$215,56,FALSE) -> 1 | K2: =VLOOKUP($A2,ScionOutput!$A$3:$BL$215,58,FALSE) -> HomFave | L2: =VLOOKUP($A2,ScionOutput!$A$3:$BL$215,59,FALSE) -> 0.01837 | M2: =VLOOKUP($A2,ScionOutput!$A$3:$BL$215,62,FALSE) -> 1 | N2: =VLOOKUP($A2,ScionOutput!$A$3:$BL$215,63,FALSE) -> 0.93 | O2: =ISNUMBER(SEARCH("Play determined by LineStatEns and StatOnlyEns agreement", AA2)) -> TRUE | P2: =VLOOKUP($A2,Outcomes!$B$3:$I$209,8,FALSE) -> 9 | Q2: =IF(R2>S2,1,IF(R2<S2,-1,0)) -> 1 | R2: =VLOOKUP($A2,Outcomes!$B$3:$I$209,5,FALSE) -> 6 | S2: =VLOOKUP($A2,Outcomes!$B$3:$I$209,6,FALSE) -> 3 | T2: =VLOOKUP($A2,Outcomes!$B$3:$I$209,7,FALSE) -> -3 | U2: =IF(T2=0,"Push",IF(G2<H2,IF(T2<0,"HomFave","VisDog"),IF(T2>0,"VisFave","HomDog"))) -> HomFave | V2: =IF(OR(T2=0,I2="No Play",J2<>1),"",IF(U2=I2,1,0)) -> 1 | W2: =IF(V2="","",IF(G2<H2,IF(K2="HomFave",ABS(G2),IF(H2<0,ABS(H2),100)),IF(K2="VisFave",ABS(H2),IF(G2<0,ABS(G2),100)))) -> 110 | X2: =IF(V2="","",IF(V2=0,0,IF(G2<H2,IF(K2="HomFave",W2+100,IF(H2<0,100+W2,W2+ABS(H2))),IF(K2="VisFave",W2+100,IF(G2<0,100+W2,W2+ABS(G2)))))) -> 210 | Y2: =IF(V2="","",X2-W2) -> 100 | Z2: =IF(V2="","",Y2/W2) -> 0.90909091 | AA2: =VLOOKUP($A2,ScionOutput!$A$3:$BL$215,64,FALSE) -> 824915. Play determined by LineStatEns and StatOnlyEns agreement.
A3: 825075 | B3: =VLOOKUP($A3,ScionOutput!$A$3:$BL$215,3,FALSE) -> 46179 | C3: =VLOOKUP($A3,ScionOutput!$A$3:$BL$215,22,FALSE) -> 1 | D3: =VLOOKUP($A3,ScionOutput!$A$3:$BL$215,23,FALSE) -> ARZ | E3: =VLOOKUP($A3,ScionOutput!$A$3:$BL$215,6,FALSE) -> 16 | F3: =VLOOKUP($A3,ScionOutput!$A$3:$BL$215,7,FALSE) -> WAS | G3: =VLOOKUP($A3,ScionOutput!$A$3:$BL$215,26,FALSE) -> -155 | H3: =VLOOKUP($A3,ScionOutput!$A$3:$BL$215,10,FALSE) -> 140 | I3: =VLOOKUP($A3,ScionOutput!$A$3:$BL$215,55,FALSE) -> HomFave | J3: =VLOOKUP($A3,ScionOutput!$A$3:$BL$215,56,FALSE) -> 0 | K3: =VLOOKUP($A3,ScionOutput!$A$3:$BL$215,58,FALSE) -> No Play | L3: =VLOOKUP($A3,ScionOutput!$A$3:$BL$215,59,FALSE) -> 0 | M3: =VLOOKUP($A3,ScionOutput!$A$3:$BL$215,62,FALSE) -> 0 | N3: =VLOOKUP($A3,ScionOutput!$A$3:$BL$215,63,FALSE) -> 0 | O3: =ISNUMBER(SEARCH("Play determined by LineStatEns and StatOnlyEns agreement", AA3)) -> FALSE | P3: =VLOOKUP($A3,Outcomes!$B$3:$I$209,8,FALSE) -> 7 | Q3: =IF(R3>S3,1,IF(R3<S3,-1,0)) -> -1 | R3: =VLOOKUP($A3,Outcomes!$B$3:$I$209,5,FALSE) -> 1 | S3: =VLOOKUP($A3,Outcomes!$B$3:$I$209,6,FALSE) -> 6 | T3: =VLOOKUP($A3,Outcomes!$B$3:$I$209,7,FALSE) -> 5 | U3: =IF(T3=0,"Push",IF(G3<H3,IF(T3<0,"HomFave","VisDog"),IF(T3>0,"VisFave","HomDog"))) -> VisDog | V3: =IF(OR(T3=0,I3="No Play",J3<>1),"",IF(U3=I3,1,0)) | W3: =IF(V3="","",IF(G3<H3,IF(K3="HomFave",ABS(G3),IF(H3<0,ABS(H3),100)),IF(K3="VisFave",ABS(H3),IF(G3<0,ABS(G3),100)))) | X3: =IF(V3="","",IF(V3=0,0,IF(G3<H3,IF(K3="HomFave",W3+100,IF(H3<0,100+W3,W3+ABS(H3))),IF(K3="VisFave",W3+100,IF(G3<0,100+W3,W3+ABS(G3)))))) | Y3: =IF(V3="","",X3-W3) | Z3: =IF(V3="","",Y3/W3) | AA3: =VLOOKUP($A3,ScionOutput!$A$3:$BL$215,64,FALSE) -> 825075. LineStatEns is NoPlay as bookie-line outside range. StatOnlyEns is NoPlay as bookie-line outside range. No play due to strategy constraints.
A4: 824669 | B4: =VLOOKUP($A4,ScionOutput!$A$3:$BL$215,3,FALSE) -> 46179 | C4: =VLOOKUP($A4,ScionOutput!$A$3:$BL$215,22,FALSE) -> 5 | D4: =VLOOKUP($A4,ScionOutput!$A$3:$BL$215,23,FALSE) -> CHC | E4: =VLOOKUP($A4,ScionOutput!$A$3:$BL$215,6,FALSE) -> 25 | F4: =VLOOKUP($A4,ScionOutput!$A$3:$BL$215,7,FALSE) -> SF | G4: =VLOOKUP($A4,ScionOutput!$A$3:$BL$215,26,FALSE) -> -140 | H4: =VLOOKUP($A4,ScionOutput!$A$3:$BL$215,10,FALSE) -> 127 | I4: =VLOOKUP($A4,ScionOutput!$A$3:$BL$215,55,FALSE) -> HomFave | J4: =VLOOKUP($A4,ScionOutput!$A$3:$BL$215,56,FALSE) -> 0 | K4: =VLOOKUP($A4,ScionOutput!$A$3:$BL$215,58,FALSE) -> No Play | L4: =VLOOKUP($A4,ScionOutput!$A$3:$BL$215,59,FALSE) -> 0 | M4: =VLOOKUP($A4,ScionOutput!$A$3:$BL$215,62,FALSE) -> 0 | N4: =VLOOKUP($A4,ScionOutput!$A$3:$BL$215,63,FALSE) -> 0 | O4: =ISNUMBER(SEARCH("Play determined by LineStatEns and StatOnlyEns agreement", AA4)) -> FALSE | P4: =VLOOKUP($A4,Outcomes!$B$3:$I$209,8,FALSE) -> 5 | Q4: =IF(R4>S4,1,IF(R4<S4,-1,0)) -> 1 | R4: =VLOOKUP($A4,Outcomes!$B$3:$I$209,5,FALSE) -> 3 | S4: =VLOOKUP($A4,Outcomes!$B$3:$I$209,6,FALSE) -> 2 | T4: =VLOOKUP($A4,Outcomes!$B$3:$I$209,7,FALSE) -> -1 | U4: =IF(T4=0,"Push",IF(G4<H4,IF(T4<0,"HomFave","VisDog"),IF(T4>0,"VisFave","HomDog"))) -> HomFave | V4: =IF(OR(T4=0,I4="No Play",J4<>1),"",IF(U4=I4,1,0)) | W4: =IF(V4="","",IF(G4<H4,IF(K4="HomFave",ABS(G4),IF(H4<0,ABS(H4),100)),IF(K4="VisFave",ABS(H4),IF(G4<0,ABS(G4),100)))) | X4: =IF(V4="","",IF(V4=0,0,IF(G4<H4,IF(K4="HomFave",W4+100,IF(H4<0,100+W4,W4+ABS(H4))),IF(K4="VisFave",W4+100,IF(G4<0,100+W4,W4+ABS(G4)))))) | Y4: =IF(V4="","",X4-W4) | Z4: =IF(V4="","",Y4/W4) | AA4: =VLOOKUP($A4,ScionOutput!$A$3:$BL$215,64,FALSE) -> 824669. LineStatEns probability points gap does not exceed threshold (no edge found)! StatOnlyEns probability points gap does not exceed threshold (no edge found)! No play due to strategy constraints.
A5: 824351 | B5: =VLOOKUP($A5,ScionOutput!$A$3:$BL$215,3,FALSE) -> 46179 | C5: =VLOOKUP($A5,ScionOutput!$A$3:$BL$215,22,FALSE) -> 8 | D5: =VLOOKUP($A5,ScionOutput!$A$3:$BL$215,23,FALSE) -> COL | E5: =VLOOKUP($A5,ScionOutput!$A$3:$BL$215,6,FALSE) -> 17 | F5: =VLOOKUP($A5,ScionOutput!$A$3:$BL$215,7,FALSE) -> MLW | G5: =VLOOKUP($A5,ScionOutput!$A$3:$BL$215,26,FALSE) -> 214 | H5: =VLOOKUP($A5,ScionOutput!$A$3:$BL$215,10,FALSE) -> -240 | I5: =VLOOKUP($A5,ScionOutput!$A$3:$BL$215,55,FALSE) -> VisFave | J5: =VLOOKUP($A5,ScionOutput!$A$3:$BL$215,56,FALSE) -> 0 | K5: =VLOOKUP($A5,ScionOutput!$A$3:$BL$215,58,FALSE) -> No Play | L5: =VLOOKUP($A5,ScionOutput!$A$3:$BL$215,59,FALSE) -> 0 | M5: =VLOOKUP($A5,ScionOutput!$A$3:$BL$215,62,FALSE) -> 0 | N5: =VLOOKUP($A5,ScionOutput!$A$3:$BL$215,63,FALSE) -> 0 | O5: =ISNUMBER(SEARCH("Play determined by LineStatEns and StatOnlyEns agreement", AA5)) -> FALSE | P5: =VLOOKUP($A5,Outcomes!$B$3:$I$209,8,FALSE) -> 8 | Q5: =IF(R5>S5,1,IF(R5<S5,-1,0)) -> -1 | R5: =VLOOKUP($A5,Outcomes!$B$3:$I$209,5,FALSE) -> 1 | S5: =VLOOKUP($A5,Outcomes!$B$3:$I$209,6,FALSE) -> 7 | T5: =VLOOKUP($A5,Outcomes!$B$3:$I$209,7,FALSE) -> 6 | U5: =IF(T5=0,"Push",IF(G5<H5,IF(T5<0,"HomFave","VisDog"),IF(T5>0,"VisFave","HomDog"))) -> VisFave | V5: =IF(OR(T5=0,I5="No Play",J5<>1),"",IF(U5=I5,1,0)) | W5: =IF(V5="","",IF(G5<H5,IF(K5="HomFave",ABS(G5),IF(H5<0,ABS(H5),100)),IF(K5="VisFave",ABS(H5),IF(G5<0,ABS(G5),100)))) | X5: =IF(V5="","",IF(V5=0,0,IF(G5<H5,IF(K5="HomFave",W5+100,IF(H5<0,100+W5,W5+ABS(H5))),IF(K5="VisFave",W5+100,IF(G5<0,100+W5,W5+ABS(G5)))))) | Y5: =IF(V5="","",X5-W5) | Z5: =IF(V5="","",Y5/W5) | AA5: =VLOOKUP($A5,ScionOutput!$A$3:$BL$215,64,FALSE) -> 824351. LineStatEns is NoPlay as bookie-line outside range. StatOnlyEns is NoPlay as bookie-line outside range. No play due to strategy constraints.
A6: 824269 | B6: =VLOOKUP($A6,ScionOutput!$A$3:$BL$215,3,FALSE) -> 46179 | C6: =VLOOKUP($A6,ScionOutput!$A$3:$BL$215,22,FALSE) -> 10 | D6: =VLOOKUP($A6,ScionOutput!$A$3:$BL$215,23,FALSE) -> DET | E6: =VLOOKUP($A6,ScionOutput!$A$3:$BL$215,6,FALSE) -> 24 | F6: =VLOOKUP($A6,ScionOutput!$A$3:$BL$215,7,FALSE) -> SEA | G6: =VLOOKUP($A6,ScionOutput!$A$3:$BL$215,26,FALSE) -> 116 | H6: =VLOOKUP($A6,ScionOutput!$A$3:$BL$215,10,FALSE) -> -128 | I6: =VLOOKUP($A6,ScionOutput!$A$3:$BL$215,55,FALSE) -> VisFave | J6: =VLOOKUP($A6,ScionOutput!$A$3:$BL$215,56,FALSE) -> 0 | K6: =VLOOKUP($A6,ScionOutput!$A$3:$BL$215,58,FALSE) -> No Play | L6: =VLOOKUP($A6,ScionOutput!$A$3:$BL$215,59,FALSE) -> 0 | M6: =VLOOKUP($A6,ScionOutput!$A$3:$BL$215,62,FALSE) -> 0 | N6: =VLOOKUP($A6,ScionOutput!$A$3:$BL$215,63,FALSE) -> 0 | O6: =ISNUMBER(SEARCH("Play determined by LineStatEns and StatOnlyEns agreement", AA6)) -> FALSE | P6: =VLOOKUP($A6,Outcomes!$B$3:$I$209,8,FALSE) -> 4 | Q6: =IF(R6>S6,1,IF(R6<S6,-1,0)) -> -1 | R6: =VLOOKUP($A6,Outcomes!$B$3:$I$209,5,FALSE) -> 0 | S6: =VLOOKUP($A6,Outcomes!$B$3:$I$209,6,FALSE) -> 4 | T6: =VLOOKUP($A6,Outcomes!$B$3:$I$209,7,FALSE) -> 4 | U6: =IF(T6=0,"Push",IF(G6<H6,IF(T6<0,"HomFave","VisDog"),IF(T6>0,"VisFave","HomDog"))) -> VisFave | V6: =IF(OR(T6=0,I6="No Play",J6<>1),"",IF(U6=I6,1,0)) | W6: =IF(V6="","",IF(G6<H6,IF(K6="HomFave",ABS(G6),IF(H6<0,ABS(H6),100)),IF(K6="VisFave",ABS(H6),IF(G6<0,ABS(G6),100)))) | X6: =IF(V6="","",IF(V6=0,0,IF(G6<H6,IF(K6="HomFave",W6+100,IF(H6<0,100+W6,W6+ABS(H6))),IF(K6="VisFave",W6+100,IF(G6<0,100+W6,W6+ABS(G6)))))) | Y6: =IF(V6="","",X6-W6) | Z6: =IF(V6="","",Y6/W6) | AA6: =VLOOKUP($A6,ScionOutput!$A$3:$BL$215,64,FALSE) -> 824269. VF plays are disallowed. No play due to strategy constraints.
A7: 823859 | B7: =VLOOKUP($A7,ScionOutput!$A$3:$BL$215,3,FALSE) -> 46179 | C7: =VLOOKUP($A7,ScionOutput!$A$3:$BL$215,22,FALSE) -> 11 | D7: =VLOOKUP($A7,ScionOutput!$A$3:$BL$215,23,FALSE) -> FLO | E7: =VLOOKUP($A7,ScionOutput!$A$3:$BL$215,6,FALSE) -> 27 | F7: =VLOOKUP($A7,ScionOutput!$A$3:$BL$215,7,FALSE) -> TB | G7: =VLOOKUP($A7,ScionOutput!$A$3:$BL$215,26,FALSE) -> 117 | H7: =VLOOKUP($A7,ScionOutput!$A$3:$BL$215,10,FALSE) -> -129 | I7: =VLOOKUP($A7,ScionOutput!$A$3:$BL$215,55,FALSE) -> VisFave | J7: =VLOOKUP($A7,ScionOutput!$A$3:$BL$215,56,FALSE) -> 0 | K7: =VLOOKUP($A7,ScionOutput!$A$3:$BL$215,58,FALSE) -> No Play | L7: =VLOOKUP($A7,ScionOutput!$A$3:$BL$215,59,FALSE) -> 0 | M7: =VLOOKUP($A7,ScionOutput!$A$3:$BL$215,62,FALSE) -> 0 | N7: =VLOOKUP($A7,ScionOutput!$A$3:$BL$215,63,FALSE) -> 0 | O7: =ISNUMBER(SEARCH("Play determined by LineStatEns and StatOnlyEns agreement", AA7)) -> FALSE | P7: =VLOOKUP($A7,Outcomes!$B$3:$I$209,8,FALSE) -> 7 | Q7: =IF(R7>S7,1,IF(R7<S7,-1,0)) -> 1 | R7: =VLOOKUP($A7,Outcomes!$B$3:$I$209,5,FALSE) -> 4 | S7: =VLOOKUP($A7,Outcomes!$B$3:$I$209,6,FALSE) -> 3 | T7: =VLOOKUP($A7,Outcomes!$B$3:$I$209,7,FALSE) -> -1 | U7: =IF(T7=0,"Push",IF(G7<H7,IF(T7<0,"HomFave","VisDog"),IF(T7>0,"VisFave","HomDog"))) -> HomDog | V7: =IF(OR(T7=0,I7="No Play",J7<>1),"",IF(U7=I7,1,0)) | W7: =IF(V7="","",IF(G7<H7,IF(K7="HomFave",ABS(G7),IF(H7<0,ABS(H7),100)),IF(K7="VisFave",ABS(H7),IF(G7<0,ABS(G7),100)))) | X7: =IF(V7="","",IF(V7=0,0,IF(G7<H7,IF(K7="HomFave",W7+100,IF(H7<0,100+W7,W7+ABS(H7))),IF(K7="VisFave",W7+100,IF(G7<0,100+W7,W7+ABS(G7)))))) | Y7: =IF(V7="","",X7-W7) | Z7: =IF(V7="","",Y7/W7) | AA7: =VLOOKUP($A7,ScionOutput!$A$3:$BL$215,64,FALSE) -> 823859. VF plays are disallowed. No play due to strategy constraints.
A8: 824184 | B8: =VLOOKUP($A8,ScionOutput!$A$3:$BL$215,3,FALSE) -> 46179 | C8: =VLOOKUP($A8,ScionOutput!$A$3:$BL$215,22,FALSE) -> 12 | D8: =VLOOKUP($A8,ScionOutput!$A$3:$BL$215,23,FALSE) -> HOU | E8: =VLOOKUP($A8,ScionOutput!$A$3:$BL$215,6,FALSE) -> 20 | F8: =VLOOKUP($A8,ScionOutput!$A$3:$BL$215,7,FALSE) -> OAK | G8: =VLOOKUP($A8,ScionOutput!$A$3:$BL$215,26,FALSE) -> -107 | H8: =VLOOKUP($A8,ScionOutput!$A$3:$BL$215,10,FALSE) -> -103 | I8: =VLOOKUP($A8,ScionOutput!$A$3:$BL$215,55,FALSE) -> VisDog | J8: =VLOOKUP($A8,ScionOutput!$A$3:$BL$215,56,FALSE) -> 0 | K8: =VLOOKUP($A8,ScionOutput!$A$3:$BL$215,58,FALSE) -> No Play | L8: =VLOOKUP($A8,ScionOutput!$A$3:$BL$215,59,FALSE) -> 0 | M8: =VLOOKUP($A8,ScionOutput!$A$3:$BL$215,62,FALSE) -> 0 | N8: =VLOOKUP($A8,ScionOutput!$A$3:$BL$215,63,FALSE) -> 0 | O8: =ISNUMBER(SEARCH("Play determined by LineStatEns and StatOnlyEns agreement", AA8)) -> FALSE | P8: =VLOOKUP($A8,Outcomes!$B$3:$I$209,8,FALSE) -> 15 | Q8: =IF(R8>S8,1,IF(R8<S8,-1,0)) -> 1 | R8: =VLOOKUP($A8,Outcomes!$B$3:$I$209,5,FALSE) -> 13 | S8: =VLOOKUP($A8,Outcomes!$B$3:$I$209,6,FALSE) -> 2 | T8: =VLOOKUP($A8,Outcomes!$B$3:$I$209,7,FALSE) -> -11 | U8: =IF(T8=0,"Push",IF(G8<H8,IF(T8<0,"HomFave","VisDog"),IF(T8>0,"VisFave","HomDog"))) -> HomFave | V8: =IF(OR(T8=0,I8="No Play",J8<>1),"",IF(U8=I8,1,0)) | W8: =IF(V8="","",IF(G8<H8,IF(K8="HomFave",ABS(G8),IF(H8<0,ABS(H8),100)),IF(K8="VisFave",ABS(H8),IF(G8<0,ABS(G8),100)))) | X8: =IF(V8="","",IF(V8=0,0,IF(G8<H8,IF(K8="HomFave",W8+100,IF(H8<0,100+W8,W8+ABS(H8))),IF(K8="VisFave",W8+100,IF(G8<0,100+W8,W8+ABS(G8)))))) | Y8: =IF(V8="","",X8-W8) | Z8: =IF(V8="","",Y8/W8) | AA8: =VLOOKUP($A8,ScionOutput!$A$3:$BL$215,64,FALSE) -> 824184. V_SP is Null, team-based avg used. NoPlay as V_SP is Null.
A9: 823942 | B9: =VLOOKUP($A9,ScionOutput!$A$3:$BL$215,3,FALSE) -> 46179 | C9: =VLOOKUP($A9,ScionOutput!$A$3:$BL$215,22,FALSE) -> 14 | D9: =VLOOKUP($A9,ScionOutput!$A$3:$BL$215,23,FALSE) -> LA | E9: =VLOOKUP($A9,ScionOutput!$A$3:$BL$215,6,FALSE) -> 4 | F9: =VLOOKUP($A9,ScionOutput!$A$3:$BL$215,7,FALSE) -> LAA | G9: =VLOOKUP($A9,ScionOutput!$A$3:$BL$215,26,FALSE) -> -312 | H9: =VLOOKUP($A9,ScionOutput!$A$3:$BL$215,10,FALSE) -> 275 | I9: =VLOOKUP($A9,ScionOutput!$A$3:$BL$215,55,FALSE) -> HomFave | J9: =VLOOKUP($A9,ScionOutput!$A$3:$BL$215,56,FALSE) -> 0 | K9: =VLOOKUP($A9,ScionOutput!$A$3:$BL$215,58,FALSE) -> No Play | L9: =VLOOKUP($A9,ScionOutput!$A$3:$BL$215,59,FALSE) -> 0 | M9: =VLOOKUP($A9,ScionOutput!$A$3:$BL$215,62,FALSE) -> 0 | N9: =VLOOKUP($A9,ScionOutput!$A$3:$BL$215,63,FALSE) -> 0 | O9: =ISNUMBER(SEARCH("Play determined by LineStatEns and StatOnlyEns agreement", AA9)) -> FALSE | P9: =VLOOKUP($A9,Outcomes!$B$3:$I$209,8,FALSE) -> 11 | Q9: =IF(R9>S9,1,IF(R9<S9,-1,0)) -> 1 | R9: =VLOOKUP($A9,Outcomes!$B$3:$I$209,5,FALSE) -> 9 | S9: =VLOOKUP($A9,Outcomes!$B$3:$I$209,6,FALSE) -> 2 | T9: =VLOOKUP($A9,Outcomes!$B$3:$I$209,7,FALSE) -> -7 | U9: =IF(T9=0,"Push",IF(G9<H9,IF(T9<0,"HomFave","VisDog"),IF(T9>0,"VisFave","HomDog"))) -> HomFave | V9: =IF(OR(T9=0,I9="No Play",J9<>1),"",IF(U9=I9,1,0)) | W9: =IF(V9="","",IF(G9<H9,IF(K9="HomFave",ABS(G9),IF(H9<0,ABS(H9),100)),IF(K9="VisFave",ABS(H9),IF(G9<0,ABS(G9),100)))) | X9: =IF(V9="","",IF(V9=0,0,IF(G9<H9,IF(K9="HomFave",W9+100,IF(H9<0,100+W9,W9+ABS(H9))),IF(K9="VisFave",W9+100,IF(G9<0,100+W9,W9+ABS(G9)))))) | Y9: =IF(V9="","",X9-W9) | Z9: =IF(V9="","",Y9/W9) | AA9: =VLOOKUP($A9,ScionOutput!$A$3:$BL$215,64,FALSE) -> 823942. LineStatEns is NoPlay as bookie-line outside range. StatOnlyEns is NoPlay as bookie-line outside range. No play due to strategy constraints.
A10: 823697 | B10: =VLOOKUP($A10,ScionOutput!$A$3:$BL$215,3,FALSE) -> 46179 | C10: =VLOOKUP($A10,ScionOutput!$A$3:$BL$215,22,FALSE) -> 15 | D10: =VLOOKUP($A10,ScionOutput!$A$3:$BL$215,23,FALSE) -> MIN | E10: =VLOOKUP($A10,ScionOutput!$A$3:$BL$215,6,FALSE) -> 13 | F10: =VLOOKUP($A10,ScionOutput!$A$3:$BL$215,7,FALSE) -> KC | G10: =VLOOKUP($A10,ScionOutput!$A$3:$BL$215,26,FALSE) -> -145 | H10: =VLOOKUP($A10,ScionOutput!$A$3:$BL$215,10,FALSE) -> 131 | I10: =VLOOKUP($A10,ScionOutput!$A$3:$BL$215,55,FALSE) -> HomFave | J10: =VLOOKUP($A10,ScionOutput!$A$3:$BL$215,56,FALSE) -> 0 | K10: =VLOOKUP($A10,ScionOutput!$A$3:$BL$215,58,FALSE) -> No Play | L10: =VLOOKUP($A10,ScionOutput!$A$3:$BL$215,59,FALSE) -> 0 | M10: =VLOOKUP($A10,ScionOutput!$A$3:$BL$215,62,FALSE) -> 0 | N10: =VLOOKUP($A10,ScionOutput!$A$3:$BL$215,63,FALSE) -> 0 | O10: =ISNUMBER(SEARCH("Play determined by LineStatEns and StatOnlyEns agreement", AA10)) -> FALSE | P10: =VLOOKUP($A10,Outcomes!$B$3:$I$209,8,FALSE) -> 5 | Q10: =IF(R10>S10,1,IF(R10<S10,-1,0)) -> -1 | R10: =VLOOKUP($A10,Outcomes!$B$3:$I$209,5,FALSE) -> 2 | S10: =VLOOKUP($A10,Outcomes!$B$3:$I$209,6,FALSE) -> 3 | T10: =VLOOKUP($A10,Outcomes!$B$3:$I$209,7,FALSE) -> 1 | U10: =IF(T10=0,"Push",IF(G10<H10,IF(T10<0,"HomFave","VisDog"),IF(T10>0,"VisFave","HomDog"))) -> VisDog | V10: =IF(OR(T10=0,I10="No Play",J10<>1),"",IF(U10=I10,1,0)) | W10: =IF(V10="","",IF(G10<H10,IF(K10="HomFave",ABS(G10),IF(H10<0,ABS(H10),100)),IF(K10="VisFave",ABS(H10),IF(G10<0,ABS(G10),100)))) | X10: =IF(V10="","",IF(V10=0,0,IF(G10<H10,IF(K10="HomFave",W10+100,IF(H10<0,100+W10,W10+ABS(H10))),IF(K10="VisFave",W10+100,IF(G10<0,100+W10,W10+ABS(G10)))))) | Y10: =IF(V10="","",X10-W10) | Z10: =IF(V10="","",Y10/W10) | AA10: =VLOOKUP($A10,ScionOutput!$A$3:$BL$215,64,FALSE) -> 823697. LineStatEns probability points gap does not exceed threshold (no edge found)! StatOnlyEns probability points gap does not exceed threshold (no edge found)! No play due to strategy constraints.
A11: 823454 | B11: =VLOOKUP($A11,ScionOutput!$A$3:$BL$215,3,FALSE) -> 46179 | C11: =VLOOKUP($A11,ScionOutput!$A$3:$BL$215,22,FALSE) -> 21 | D11: =VLOOKUP($A11,ScionOutput!$A$3:$BL$215,23,FALSE) -> PHI | E11: =VLOOKUP($A11,ScionOutput!$A$3:$BL$215,6,FALSE) -> 9 | F11: =VLOOKUP($A11,ScionOutput!$A$3:$BL$215,7,FALSE) -> CWS | G11: =VLOOKUP($A11,ScionOutput!$A$3:$BL$215,26,FALSE) -> -123 | H11: =VLOOKUP($A11,ScionOutput!$A$3:$BL$215,10,FALSE) -> 112 | I11: =VLOOKUP($A11,ScionOutput!$A$3:$BL$215,55,FALSE) -> HomFave | J11: =VLOOKUP($A11,ScionOutput!$A$3:$BL$215,56,FALSE) -> 1 | K11: =VLOOKUP($A11,ScionOutput!$A$3:$BL$215,58,FALSE) -> No Play | L11: =VLOOKUP($A11,ScionOutput!$A$3:$BL$215,59,FALSE) -> 0 | M11: =VLOOKUP($A11,ScionOutput!$A$3:$BL$215,62,FALSE) -> 0 | N11: =VLOOKUP($A11,ScionOutput!$A$3:$BL$215,63,FALSE) -> 0 | O11: =ISNUMBER(SEARCH("Play determined by LineStatEns and StatOnlyEns agreement", AA11)) -> FALSE | P11: =VLOOKUP($A11,Outcomes!$B$3:$I$209,8,FALSE) -> 9 | Q11: =IF(R11>S11,1,IF(R11<S11,-1,0)) -> -1 | R11: =VLOOKUP($A11,Outcomes!$B$3:$I$209,5,FALSE) -> 3 | S11: =VLOOKUP($A11,Outcomes!$B$3:$I$209,6,FALSE) -> 6 | T11: =VLOOKUP($A11,Outcomes!$B$3:$I$209,7,FALSE) -> 3 | U11: =IF(T11=0,"Push",IF(G11<H11,IF(T11<0,"HomFave","VisDog"),IF(T11>0,"VisFave","HomDog"))) -> VisDog | V11: =IF(OR(T11=0,I11="No Play",J11<>1),"",IF(U11=I11,1,0)) -> 0 | W11: =IF(V11="","",IF(G11<H11,IF(K11="HomFave",ABS(G11),IF(H11<0,ABS(H11),100)),IF(K11="VisFave",ABS(H11),IF(G11<0,ABS(G11),100)))) -> 100 | X11: =IF(V11="","",IF(V11=0,0,IF(G11<H11,IF(K11="HomFave",W11+100,IF(H11<0,100+W11,W11+ABS(H11))),IF(K11="VisFave",W11+100,IF(G11<0,100+W11,W11+ABS(G11)))))) -> 0 | Y11: =IF(V11="","",X11-W11) -> -100 | Z11: =IF(V11="","",Y11/W11) -> -1 | AA11: =VLOOKUP($A11,ScionOutput!$A$3:$BL$215,64,FALSE) -> 823454. LineStatEns probability points gap does not exceed threshold (no edge found)! No play due to strategy constraints.
A12: 823292 | B12: =VLOOKUP($A12,ScionOutput!$A$3:$BL$215,3,FALSE) -> 46179 | C12: =VLOOKUP($A12,ScionOutput!$A$3:$BL$215,22,FALSE) -> 23 | D12: =VLOOKUP($A12,ScionOutput!$A$3:$BL$215,23,FALSE) -> SD | E12: =VLOOKUP($A12,ScionOutput!$A$3:$BL$215,6,FALSE) -> 18 | F12: =VLOOKUP($A12,ScionOutput!$A$3:$BL$215,7,FALSE) -> NYM | G12: =VLOOKUP($A12,ScionOutput!$A$3:$BL$215,26,FALSE) -> 104 | H12: =VLOOKUP($A12,ScionOutput!$A$3:$BL$215,10,FALSE) -> -115 | I12: =VLOOKUP($A12,ScionOutput!$A$3:$BL$215,55,FALSE) -> VisFave | J12: =VLOOKUP($A12,ScionOutput!$A$3:$BL$215,56,FALSE) -> 0 | K12: =VLOOKUP($A12,ScionOutput!$A$3:$BL$215,58,FALSE) -> No Play | L12: =VLOOKUP($A12,ScionOutput!$A$3:$BL$215,59,FALSE) -> 0 | M12: =VLOOKUP($A12,ScionOutput!$A$3:$BL$215,62,FALSE) -> 0 | N12: =VLOOKUP($A12,ScionOutput!$A$3:$BL$215,63,FALSE) -> 0 | O12: =ISNUMBER(SEARCH("Play determined by LineStatEns and StatOnlyEns agreement", AA12)) -> FALSE | P12: =VLOOKUP($A12,Outcomes!$B$3:$I$209,8,FALSE) -> 5 | Q12: =IF(R12>S12,1,IF(R12<S12,-1,0)) -> 1 | R12: =VLOOKUP($A12,Outcomes!$B$3:$I$209,5,FALSE) -> 3 | S12: =VLOOKUP($A12,Outcomes!$B$3:$I$209,6,FALSE) -> 2 | T12: =VLOOKUP($A12,Outcomes!$B$3:$I$209,7,FALSE) -> -1 | U12: =IF(T12=0,"Push",IF(G12<H12,IF(T12<0,"HomFave","VisDog"),IF(T12>0,"VisFave","HomDog"))) -> HomDog | V12: =IF(OR(T12=0,I12="No Play",J12<>1),"",IF(U12=I12,1,0)) | W12: =IF(V12="","",IF(G12<H12,IF(K12="HomFave",ABS(G12),IF(H12<0,ABS(H12),100)),IF(K12="VisFave",ABS(H12),IF(G12<0,ABS(G12),100)))) | X12: =IF(V12="","",IF(V12=0,0,IF(G12<H12,IF(K12="HomFave",W12+100,IF(H12<0,100+W12,W12+ABS(H12))),IF(K12="VisFave",W12+100,IF(G12<0,100+W12,W12+ABS(G12)))))) | Y12: =IF(V12="","",X12-W12) | Z12: =IF(V12="","",Y12/W12) | AA12: =VLOOKUP($A12,ScionOutput!$A$3:$BL$215,64,FALSE) -> 823292. VF plays are disallowed. No play due to strategy constraints.
A13: 823048 | B13: =VLOOKUP($A13,ScionOutput!$A$3:$BL$215,3,FALSE) -> 46179 | C13: =VLOOKUP($A13,ScionOutput!$A$3:$BL$215,22,FALSE) -> 26 | D13: =VLOOKUP($A13,ScionOutput!$A$3:$BL$215,23,FALSE) -> STL | E13: =VLOOKUP($A13,ScionOutput!$A$3:$BL$215,6,FALSE) -> 6 | F13: =VLOOKUP($A13,ScionOutput!$A$3:$BL$215,7,FALSE) -> CIN | G13: =VLOOKUP($A13,ScionOutput!$A$3:$BL$215,26,FALSE) -> -125 | H13: =VLOOKUP($A13,ScionOutput!$A$3:$BL$215,10,FALSE) -> 113 | I13: =VLOOKUP($A13,ScionOutput!$A$3:$BL$215,55,FALSE) -> HomFave | J13: =VLOOKUP($A13,ScionOutput!$A$3:$BL$215,56,FALSE) -> 0 | K13: =VLOOKUP($A13,ScionOutput!$A$3:$BL$215,58,FALSE) -> No Play | L13: =VLOOKUP($A13,ScionOutput!$A$3:$BL$215,59,FALSE) -> 0 | M13: =VLOOKUP($A13,ScionOutput!$A$3:$BL$215,62,FALSE) -> 0 | N13: =VLOOKUP($A13,ScionOutput!$A$3:$BL$215,63,FALSE) -> 0 | O13: =ISNUMBER(SEARCH("Play determined by LineStatEns and StatOnlyEns agreement", AA13)) -> FALSE | P13: =VLOOKUP($A13,Outcomes!$B$3:$I$209,8,FALSE) -> 11 | Q13: =IF(R13>S13,1,IF(R13<S13,-1,0)) -> 1 | R13: =VLOOKUP($A13,Outcomes!$B$3:$I$209,5,FALSE) -> 6 | S13: =VLOOKUP($A13,Outcomes!$B$3:$I$209,6,FALSE) -> 5 | T13: =VLOOKUP($A13,Outcomes!$B$3:$I$209,7,FALSE) -> -1 | U13: =IF(T13=0,"Push",IF(G13<H13,IF(T13<0,"HomFave","VisDog"),IF(T13>0,"VisFave","HomDog"))) -> HomFave | V13: =IF(OR(T13=0,I13="No Play",J13<>1),"",IF(U13=I13,1,0)) | W13: =IF(V13="","",IF(G13<H13,IF(K13="HomFave",ABS(G13),IF(H13<0,ABS(H13),100)),IF(K13="VisFave",ABS(H13),IF(G13<0,ABS(G13),100)))) | X13: =IF(V13="","",IF(V13=0,0,IF(G13<H13,IF(K13="HomFave",W13+100,IF(H13<0,100+W13,W13+ABS(H13))),IF(K13="VisFave",W13+100,IF(G13<0,100+W13,W13+ABS(G13)))))) | Y13: =IF(V13="","",X13-W13) | Z13: =IF(V13="","",Y13/W13) | AA13: =VLOOKUP($A13,ScionOutput!$A$3:$BL$215,64,FALSE) -> 823048. LineStatEns probability points gap does not exceed threshold (no edge found)! StatOnlyEns probability points gap does not exceed threshold (no edge found)! No play due to strategy constraints.
... A209: 822883 | B209: =VLOOKUP($A209,ScionOutput!$A$3:$BL$215,3,FALSE) -> 46194 | C209: =VLOOKUP($A209,ScionOutput!$A$3:$BL$215,22,FALSE) -> 28 | D209: =VLOOKUP($A209,ScionOutput!$A$3:$BL$215,23,FALSE) -> TEX | E209: =VLOOKUP($A209,ScionOutput!$A$3:$BL$215,6,FALSE) -> 23 | F209: =VLOOKUP($A209,ScionOutput!$A$3:$BL$215,7,FALSE) -> SD | G209: =VLOOKUP($A209,ScionOutput!$A$3:$BL$215,26,FALSE) -> -160 | H209: =VLOOKUP($A209,ScionOutput!$A$3:$BL$215,10,FALSE) -> 147 | I209: =VLOOKUP($A209,ScionOutput!$A$3:$BL$215,55,FALSE) -> HomFave | J209: =VLOOKUP($A209,ScionOutput!$A$3:$BL$215,56,FALSE) -> 0 | K209: =VLOOKUP($A209,ScionOutput!$A$3:$BL$215,58,FALSE) -> No Play | L209: =VLOOKUP($A209,ScionOutput!$A$3:$BL$215,59,FALSE) -> 0 | M209: =VLOOKUP($A209,ScionOutput!$A$3:$BL$215,62,FALSE) -> 0 | N209: =VLOOKUP($A209,ScionOutput!$A$3:$BL$215,63,FALSE) -> 0 | O209: =ISNUMBER(SEARCH("Play determined by LineStatEns and StatOnlyEns agreement", AA209)) -> FALSE | P209: =VLOOKUP($A209,Outcomes!$B$3:$I$209,8,FALSE) -> 7 | Q209: =IF(R209>S209,1,IF(R209<S209,-1,0)) -> 1 | R209: =VLOOKUP($A209,Outcomes!$B$3:$I$209,5,FALSE) -> 4 | S209: =VLOOKUP($A209,Outcomes!$B$3:$I$209,6,FALSE) -> 3 | T209: =VLOOKUP($A209,Outcomes!$B$3:$I$209,7,FALSE) -> -1 | U209: =IF(T209=0,"Push",IF(G209<H209,IF(T209<0,"HomFave","VisDog"),IF(T209>0,"VisFave","HomDog"))) -> HomFave | V209: =IF(OR(T209=0,I209="No Play",J209<>1),"",IF(U209=I209,1,0)) | W209: =IF(V209="","",IF(G209<H209,IF(K209="HomFave",ABS(G209),IF(H209<0,ABS(H209),100)),IF(K209="VisFave",ABS(H209),IF(G209<0,ABS(G209),100)))) | X209: =IF(V209="","",IF(V209=0,0,IF(G209<H209,IF(K209="HomFave",W209+100,IF(H209<0,100+W209,W209+ABS(H209))),IF(K209="VisFave",W209+100,IF(G209<0,100+W209,W209+ABS(G209)))))) | Y209: =IF(V209="","",X209-W209) | Z209: =IF(V209="","",Y209/W209) | AA209: =VLOOKUP($A209,ScionOutput!$A$3:$BL$215,64,FALSE) -> 822883. LineStatEns is NoPlay as bookie-line outside range. StatOnlyEns is NoPlay as bookie-line outside range. No play due to strategy constraints.
D210: x | F210: x | G210: x | H210: x | I210: x | J210: x | K210: x | L210: x | M210: x | N210: x | O210: x | V210: x | W210: =SUM(W2:W209) -> 4809 | X210: =SUM(X2:X209) -> 5045 | Y210: =SUM(Y2:Y209) -> 236 | Z210: =IF(V210="","",Y210/W210) -> 0.049074652 | AA210: x
U211: #Games | V211: =COUNT(T2:T209) -> 208
U212: #Plays | V212: =COUNT(V2:V209) -> 47
U213: %Games | V213: =V212/V211 -> 0.22596154
U214: #Win | V214: =SUM(V2:V209) -> 24
U215: %WinRate | V215: =V214/V212 -> 0.5106383
U216: invest | V216: =W210 -> 4809
U217: return | V217: =X210 -> 5045
U218: profit | V218: =Y210 -> 236
U219: %ROI | V219: =IF(V216=0,0,V218/V216) -> 0.049074652
T221: HF | U221: plays | V221: =COUNTIFS($K$2:$K$209,"HomFave",$V$2:$V$209,"1")+COUNTIFS($K$2:$K$209,"HomFave",$V$2:$V$209,"0") -> 7 | X221: VD | Y221: plays | Z221: =COUNTIFS($K$2:$K$209,"VisDog",$V$2:$V$209,"1")+COUNTIFS($K$2:$K$209,"VisDog",$V$2:$V$209,"0") -> 10
U222: wins | V222: =COUNTIFS($K$2:$K$209,"HomFave",$V$2:$V$209,"1") -> 5 | Y222: wins | Z222: =COUNTIFS($K$2:$K$209,"VisDog",$V$2:$V$209,"1") -> 3
U223: %WR | V223: =IF(V221=0,0,V222/V221) -> 0.71428571 | Y223: %WR | Z223: =IF(Z221=0,0,Z222/Z221) -> 0.3
U224: invest | V224: =SUMIFS($W$2:$W$209,$K$2:$K$209,"HomFave") -> 787 | Y224: invest | Z224: =SUMIFS($W$2:$W$209,$K$2:$K$209,"VisDog") -> 1006
U225: return | V225: =SUMIFS($X$2:$X$209,$K$2:$K$209,"HomFave") -> 1053 | Y225: return | Z225: =SUMIFS($X$2:$X$209,$K$2:$K$209,"VisDog") -> 621
U226: profit | V226: =V225-V224 -> 266 | Y226: profit | Z226: =Z225-Z224 -> -385
U227: %ROI | V227: =IF(V224=0,0,V226/V224) -> 0.33799238 | Y227: %ROI | Z227: =IF(Z224=0,0,Z226/Z224) -> -0.38270378
T229: VF | U229: plays | V229: =COUNTIFS($K$2:$K$209,"VisFave",$V$2:$V$209,"1")+COUNTIFS($K$2:$K$209,"VisFave",$V$2:$V$209,"0") -> 0 | X229: HD | Y229: plays | Z229: =COUNTIFS($K$2:$K$209,"HomDog",$V$2:$V$209,"1")+COUNTIFS($K$2:$K$209,"HomDog",$V$2:$V$209,"0") -> 4
U230: wins | V230: =COUNTIFS($K$2:$K$209,"VisFave",$V$2:$V$209,"1") -> 0 | Y230: wins | Z230: =COUNTIFS($K$2:$K$209,"HomDog",$V$2:$V$209,"1") -> 1
U231: %WR | V231: =IF(V229=0,0,V230/V229) -> 0 | Y231: %WR | Z231: =IF(Z229=0,0,Z230/Z229) -> 0.25
U232: invest | V232: =SUMIFS($W$2:$W$209,$K$2:$K$209,"VisFave") -> 0 | Y232: invest | Z232: =SUMIFS($W$2:$W$209,$K$2:$K$209,"HomDog") -> 403
U233: return | V233: =SUMIFS($X$2:$X$209,$K$2:$K$209,"VisFave") -> 0 | Y233: return | Z233: =SUMIFS($X$2:$X$209,$K$2:$K$209,"HomDog") -> 202
U234: profit | V234: =V233-V232 -> 0 | Y234: profit | Z234: =Z233-Z232 -> -201
U235: %ROI | V235: =IF(V232=0,0,V234/V232) -> 0 | Y235: %ROI | Z235: =IF(Z232=0,0,Z234/Z232) -> -0.49875931

Sheet AgreeOnly
A1: G_Id | B1: G_Date | C1: G_H_Id | D1: HNAME | E1: G_V_Id | F1: VNAME | G1: H_Bookie_Bet_Price | H1: V_Bookie_Bet_Price | I1: Scion_Side_Play_Position | J1: Scion_H_ProbabilityEdge | K1: Scion_Side_Stars | L1: Scion_Side_Play_Confidence | M1: PlayByAgreement | N1: G_Bookie_TotalOver | O1: G_PH_Win | P1: G_H_Runs | Q1: G_V_Runs | R1: G_Actual_Runs_Diff | S1: Winning_Position | T1: WinBet? | U1: Invest | V1: Return | W1: Proft | X1: %ROI | Y1: Comments
A2: 824915 | B2: =VLOOKUP($A2,ScionOutput!$A$3:$BL$215,3,FALSE) -> 46179 | C2: =VLOOKUP($A2,ScionOutput!$A$3:$BL$215,22,FALSE) -> 0 | D2: =VLOOKUP($A2,ScionOutput!$A$3:$BL$215,23,FALSE) -> ATL | E2: =VLOOKUP($A2,ScionOutput!$A$3:$BL$215,6,FALSE) -> 22 | F2: =VLOOKUP($A2,ScionOutput!$A$3:$BL$215,7,FALSE) -> PIT | G2: =VLOOKUP($A2,ScionOutput!$A$3:$BL$215,26,FALSE) -> -110 | H2: =VLOOKUP($A2,ScionOutput!$A$3:$BL$215,10,FALSE) -> 100 | I2: =VLOOKUP($A2,ScionOutput!$A$3:$BL$215,58,FALSE) -> HomFave | J2: =VLOOKUP($A2,ScionOutput!$A$3:$BL$215,59,FALSE) -> 0.01837 | K2: =VLOOKUP($A2,ScionOutput!$A$3:$BL$215,62,FALSE) -> 1 | L2: =VLOOKUP($A2,ScionOutput!$A$3:$BL$215,63,FALSE) -> 0.93 | M2: =ISNUMBER(SEARCH("Play determined by LineStatEns and StatOnlyEns agreement", Y2)) -> TRUE | N2: =VLOOKUP($A2,Outcomes!$B$3:$I$209,8,FALSE) -> 9 | O2: =IF(P2>Q2,1,IF(P2<Q2,-1,0)) -> 1 | P2: =VLOOKUP($A2,Outcomes!$B$3:$I$209,5,FALSE) -> 6 | Q2: =VLOOKUP($A2,Outcomes!$B$3:$I$209,6,FALSE) -> 3 | R2: =VLOOKUP($A2,Outcomes!$B$3:$I$209,7,FALSE) -> -3 | S2: =IF(R2=0,"Push",IF(G2<H2,IF(R2<0,"HomFave","VisDog"),IF(R2>0,"VisFave","HomDog"))) -> HomFave | T2: =IF(OR(R2=0,I2="No Play",M2<>TRUE),"",IF(S2=I2,1,0)) -> 1 | U2: =IF(T2="","",IF(G2<H2,IF(I2="HomFave",ABS(G2),IF(H2<0,ABS(H2),100)),IF(I2="VisFave",ABS(H2),IF(G2<0,ABS(G2),100)))) -> 110 | V2: =IF(T2="","",IF(T2=0,0,IF(G2<H2,IF(I2="HomFave",U2+100,IF(H2<0,100+U2,U2+ABS(H2))),IF(I2="VisFave",U2+100,IF(G2<0,100+U2,U2+ABS(G2)))))) -> 210 | W2: =IF(T2="","",V2-U2) -> 100 | X2: =IF(T2="","",W2/U2) -> 0.90909091 | Y2: =VLOOKUP($A2,ScionOutput!$A$3:$BL$215,64,FALSE) -> 824915. Play determined by LineStatEns and StatOnlyEns agreement.
A3: 825075 | B3: =VLOOKUP($A3,ScionOutput!$A$3:$BL$215,3,FALSE) -> 46179 | C3: =VLOOKUP($A3,ScionOutput!$A$3:$BL$215,22,FALSE) -> 1 | D3: =VLOOKUP($A3,ScionOutput!$A$3:$BL$215,23,FALSE) -> ARZ | E3: =VLOOKUP($A3,ScionOutput!$A$3:$BL$215,6,FALSE) -> 16 | F3: =VLOOKUP($A3,ScionOutput!$A$3:$BL$215,7,FALSE) -> WAS | G3: =VLOOKUP($A3,ScionOutput!$A$3:$BL$215,26,FALSE) -> -155 | H3: =VLOOKUP($A3,ScionOutput!$A$3:$BL$215,10,FALSE) -> 140 | I3: =VLOOKUP($A3,ScionOutput!$A$3:$BL$215,58,FALSE) -> No Play | J3: =VLOOKUP($A3,ScionOutput!$A$3:$BL$215,59,FALSE) -> 0 | K3: =VLOOKUP($A3,ScionOutput!$A$3:$BL$215,62,FALSE) -> 0 | L3: =VLOOKUP($A3,ScionOutput!$A$3:$BL$215,63,FALSE) -> 0 | M3: =ISNUMBER(SEARCH("Play determined by LineStatEns and StatOnlyEns agreement", Y3)) -> FALSE | N3: =VLOOKUP($A3,Outcomes!$B$3:$I$209,8,FALSE) -> 7 | O3: =IF(P3>Q3,1,IF(P3<Q3,-1,0)) -> -1 | P3: =VLOOKUP($A3,Outcomes!$B$3:$I$209,5,FALSE) -> 1 | Q3: =VLOOKUP($A3,Outcomes!$B$3:$I$209,6,FALSE) -> 6 | R3: =VLOOKUP($A3,Outcomes!$B$3:$I$209,7,FALSE) -> 5 | S3: =IF(R3=0,"Push",IF(G3<H3,IF(R3<0,"HomFave","VisDog"),IF(R3>0,"VisFave","HomDog"))) -> VisDog | T3: =IF(OR(R3=0,I3="No Play",M3<>TRUE),"",IF(S3=I3,1,0)) | U3: =IF(T3="","",IF(G3<H3,IF(I3="HomFave",ABS(G3),IF(H3<0,ABS(H3),100)),IF(I3="VisFave",ABS(H3),IF(G3<0,ABS(G3),100)))) | V3: =IF(T3="","",IF(T3=0,0,IF(G3<H3,IF(I3="HomFave",U3+100,IF(H3<0,100+U3,U3+ABS(H3))),IF(I3="VisFave",U3+100,IF(G3<0,100+U3,U3+ABS(G3)))))) | W3: =IF(T3="","",V3-U3) | X3: =IF(T3="","",W3/U3) | Y3: =VLOOKUP($A3,ScionOutput!$A$3:$BL$215,64,FALSE) -> 825075. LineStatEns is NoPlay as bookie-line outside range. StatOnlyEns is NoPlay as bookie-line outside range. No play due to strategy constraints.
